2017-02-21 16:51:28,612  - ERROR :  HTTPConnectionPool(host='127.0.0.1', port=8000): Max retries exceeded with url: /asset (Caused by NewConnectionError('<requests.packages.urllib3.connection.HTTPConnection object at 0x101b6d6a0>: Failed to establish a new connection: [Errno 61] Connection refused',))
2017-02-22 11:44:44,079  - ERROR :  HTTPConnectionPool(host='127.0.0.1', port=8000): Max retries exceeded with url: /asset (Caused by NewConnectionError('<requests.packages.urllib3.connection.HTTPConnection object at 0x1023504a8>: Failed to establish a new connection: [Errno 61] Connection refused',))
2017-02-22 17:29:14,336  - ERROR :  ('Connection aborted.', RemoteDisconnected('Remote end closed connection without response',))
2017-02-22 18:10:43,275  - ERROR :  API授权失败
2017-02-22 18:11:56,736  - ERROR :  API授权失败
2017-02-22 18:12:40,274  - ERROR :  API授权失败
2017-02-22 18:12:48,260  - ERROR :  API授权失败
2017-02-22 18:13:55,698  - ERROR :  API授权失败
2017-02-22 18:14:13,697  - ERROR :  API授权失败
2017-02-22 19:02:36,583  - ERROR :  None
2017-02-23 09:17:51,995  - ERROR :  资产不存在
2017-02-23 09:20:58,971  - ERROR :  资产不存在
2017-02-23 09:40:52,124  - ERROR :  资产更新异常
2017-02-23 09:41:58,601  - ERROR :  资产更新异常
2017-02-23 09:49:12,592  - ERROR :  资产更新异常
2017-02-23 09:50:17,132  - ERROR :  资产更新异常
2017-02-23 09:52:17,621  - ERROR :  资产更新异常
2017-02-23 09:55:15,712  - ERROR :  资产更新异常
2017-02-23 09:56:33,072  - ERROR :  资产更新异常
2017-02-23 10:00:09,356  - ERROR :  资产更新异常
2017-02-23 10:01:32,992  - ERROR :  资产更新异常
2017-02-23 10:02:45,313  - ERROR :  资产更新异常
2017-04-14 12:20:20,821  - ERROR :  失败
2019-07-26 09:54:37,782  - ERROR :   Mysql info collect fail Traceback (most recent call last):
  File "/Users/yky/PycharmProjects/cmdb/AutoClient/src/plugins/database.py", line 49, in linux
    output = open(os.path.join(BASEDIR, 'files/database.out'), 'r').read()
FileNotFoundError: [Errno 2] No such file or directory: '/Users/yky/PycharmProjects/cmdb/AutoClient/files/database.out'

2019-07-26 09:55:39,119  - ERROR :   Mysql info collect fail Traceback (most recent call last):
  File "/Users/yky/PycharmProjects/cmdb/AutoClient/src/plugins/database.py", line 50, in linux
    output = open(os.path.join(BASEDIR, 'files/database.out'), 'r').read()
FileNotFoundError: [Errno 2] No such file or directory: '/Users/yky/PycharmProjects/cmdb/AutoClient/files/database.out'

2019-07-26 09:56:52,469  - ERROR :   Mysql info collect fail Traceback (most recent call last):
  File "/Users/yky/PycharmProjects/cmdb/AutoClient/src/plugins/database.py", line 59, in linux
    ser_db_list = database_obj.getinfo(settings.SERVER_DATABASE_CONF['sql'], )
  File "/Users/yky/PycharmProjects/cmdb/AutoClient/src/plugins/database.py", line 29, in getinfo
    charset='utf8')
  File "/Library/Frameworks/Python.framework/Versions/3.6/lib/python3.6/site-packages/pymysql/__init__.py", line 94, in Connect
    return Connection(*args, **kwargs)
  File "/Library/Frameworks/Python.framework/Versions/3.6/lib/python3.6/site-packages/pymysql/connections.py", line 325, in __init__
    self.connect()
  File "/Library/Frameworks/Python.framework/Versions/3.6/lib/python3.6/site-packages/pymysql/connections.py", line 589, in connect
    self.host_info = "socket %s:%d" % (self.host, self.port)
TypeError: %d format: a number is required, not str

2019-07-26 09:57:21,518  - ERROR :   Mysql info collect fail Traceback (most recent call last):
  File "/Users/yky/PycharmProjects/cmdb/AutoClient/src/plugins/database.py", line 58, in linux
    ser_db_list = database_obj.getinfo(settings.SERVER_DATABASE_CONF['sql'], )
  File "/Users/yky/PycharmProjects/cmdb/AutoClient/src/plugins/database.py", line 29, in getinfo
    charset='utf8')
  File "/Library/Frameworks/Python.framework/Versions/3.6/lib/python3.6/site-packages/pymysql/__init__.py", line 94, in Connect
    return Connection(*args, **kwargs)
  File "/Library/Frameworks/Python.framework/Versions/3.6/lib/python3.6/site-packages/pymysql/connections.py", line 325, in __init__
    self.connect()
  File "/Library/Frameworks/Python.framework/Versions/3.6/lib/python3.6/site-packages/pymysql/connections.py", line 589, in connect
    self.host_info = "socket %s:%d" % (self.host, self.port)
TypeError: %d format: a number is required, not str

2019-07-26 09:57:37,766  - ERROR :   Mysql info collect fail Traceback (most recent call last):
  File "/Users/yky/PycharmProjects/cmdb/AutoClient/src/plugins/database.py", line 59, in linux
    ser_db_list = database_obj.getinfo(settings.SERVER_DATABASE_CONF['sql'], )
  File "/Users/yky/PycharmProjects/cmdb/AutoClient/src/plugins/database.py", line 29, in getinfo
    charset='utf8')
  File "/Library/Frameworks/Python.framework/Versions/3.6/lib/python3.6/site-packages/pymysql/__init__.py", line 94, in Connect
    return Connection(*args, **kwargs)
  File "/Library/Frameworks/Python.framework/Versions/3.6/lib/python3.6/site-packages/pymysql/connections.py", line 325, in __init__
    self.connect()
  File "/Library/Frameworks/Python.framework/Versions/3.6/lib/python3.6/site-packages/pymysql/connections.py", line 589, in connect
    self.host_info = "socket %s:%d" % (self.host, self.port)
TypeError: %d format: a number is required, not str

2019-07-26 09:58:00,849  - ERROR :   Mysql info collect fail Traceback (most recent call last):
  File "/Users/yky/PycharmProjects/cmdb/AutoClient/src/plugins/database.py", line 58, in linux
    ser_db_list = database_obj.getinfo(settings.SERVER_DATABASE_CONF['sql'], )
  File "/Users/yky/PycharmProjects/cmdb/AutoClient/src/plugins/database.py", line 29, in getinfo
    charset='utf8')
  File "/Library/Frameworks/Python.framework/Versions/3.6/lib/python3.6/site-packages/pymysql/__init__.py", line 94, in Connect
    return Connection(*args, **kwargs)
  File "/Library/Frameworks/Python.framework/Versions/3.6/lib/python3.6/site-packages/pymysql/connections.py", line 325, in __init__
    self.connect()
  File "/Library/Frameworks/Python.framework/Versions/3.6/lib/python3.6/site-packages/pymysql/connections.py", line 589, in connect
    self.host_info = "socket %s:%d" % (self.host, self.port)
TypeError: %d format: a number is required, not str

2019-07-26 09:58:28,393  - ERROR :   Mysql info collect fail Traceback (most recent call last):
  File "/Users/yky/PycharmProjects/cmdb/AutoClient/src/plugins/database.py", line 59, in linux
    ser_db_list = database_obj.getinfo(settings.SERVER_DATABASE_CONF['sql'], )
  File "/Users/yky/PycharmProjects/cmdb/AutoClient/src/plugins/database.py", line 29, in getinfo
    charset='utf8')
  File "/Library/Frameworks/Python.framework/Versions/3.6/lib/python3.6/site-packages/pymysql/__init__.py", line 94, in Connect
    return Connection(*args, **kwargs)
  File "/Library/Frameworks/Python.framework/Versions/3.6/lib/python3.6/site-packages/pymysql/connections.py", line 325, in __init__
    self.connect()
  File "/Library/Frameworks/Python.framework/Versions/3.6/lib/python3.6/site-packages/pymysql/connections.py", line 589, in connect
    self.host_info = "socket %s:%d" % (self.host, self.port)
TypeError: %d format: a number is required, not str

2019-07-26 09:58:35,528  - ERROR :   Mysql info collect fail Traceback (most recent call last):
  File "/Users/yky/PycharmProjects/cmdb/AutoClient/src/plugins/database.py", line 59, in linux
    ser_db_list = database_obj.getinfo(settings.SERVER_DATABASE_CONF['sql'], )
  File "/Users/yky/PycharmProjects/cmdb/AutoClient/src/plugins/database.py", line 29, in getinfo
    charset='utf8')
  File "/Library/Frameworks/Python.framework/Versions/3.6/lib/python3.6/site-packages/pymysql/__init__.py", line 94, in Connect
    return Connection(*args, **kwargs)
  File "/Library/Frameworks/Python.framework/Versions/3.6/lib/python3.6/site-packages/pymysql/connections.py", line 325, in __init__
    self.connect()
  File "/Library/Frameworks/Python.framework/Versions/3.6/lib/python3.6/site-packages/pymysql/connections.py", line 589, in connect
    self.host_info = "socket %s:%d" % (self.host, self.port)
TypeError: %d format: a number is required, not str

2019-07-26 10:02:10,610  - ERROR :   Mysql info collect fail Traceback (most recent call last):
  File "/Users/yky/PycharmProjects/cmdb/AutoClient/src/plugins/database.py", line 55, in linux
    passwd=settings.SERVER_DATABASE_CONF['password'])
TypeError: __init__() missing 1 required positional argument: 'db'

2019-07-29 11:47:13,351  - ERROR :  172.16.111.131 BasicPlugin Error:Traceback (most recent call last):
  File "/Users/yky/PycharmProjects/cmdb_db/AutoClient/src/plugins/basic.py", line 47, in linux
    'os_platform': self.os_platform(),
  File "/Users/yky/PycharmProjects/cmdb_db/AutoClient/src/plugins/basic.py", line 17, in os_platform
    output = self.exec_shell_cmd('uname')
  File "/Users/yky/PycharmProjects/cmdb_db/AutoClient/src/plugins/base.py", line 45, in exec_shell_cmd
    output = func(cmd)
  File "/Users/yky/PycharmProjects/cmdb_db/AutoClient/src/plugins/base.py", line 26, in ssh
    private_key = paramiko.RSAKey.from_private_key_file(settings.SSH_PRIVATE_KEY)
  File "/Library/Frameworks/Python.framework/Versions/3.6/lib/python3.6/site-packages/paramiko/pkey.py", line 206, in from_private_key_file
    key = cls(filename=filename, password=password)
  File "/Library/Frameworks/Python.framework/Versions/3.6/lib/python3.6/site-packages/paramiko/rsakey.py", line 55, in __init__
    self._from_private_key_file(filename, password)
  File "/Library/Frameworks/Python.framework/Versions/3.6/lib/python3.6/site-packages/paramiko/rsakey.py", line 175, in _from_private_key_file
    data = self._read_private_key_file("RSA", filename, password)
  File "/Library/Frameworks/Python.framework/Versions/3.6/lib/python3.6/site-packages/paramiko/pkey.py", line 278, in _read_private_key_file
    with open(filename, "r") as f:
FileNotFoundError: [Errno 2] No such file or directory: '/root/.ssh/id_rsa'

2019-07-29 11:47:13,352  - ERROR :  172.16.111.131 BasicPlugin Error:Traceback (most recent call last):
  File "/Users/yky/PycharmProjects/cmdb_db/AutoClient/src/plugins/basic.py", line 47, in linux
    'os_platform': self.os_platform(),
  File "/Users/yky/PycharmProjects/cmdb_db/AutoClient/src/plugins/basic.py", line 17, in os_platform
    output = self.exec_shell_cmd('uname')
  File "/Users/yky/PycharmProjects/cmdb_db/AutoClient/src/plugins/base.py", line 45, in exec_shell_cmd
    output = func(cmd)
  File "/Users/yky/PycharmProjects/cmdb_db/AutoClient/src/plugins/base.py", line 26, in ssh
    private_key = paramiko.RSAKey.from_private_key_file(settings.SSH_PRIVATE_KEY)
  File "/Library/Frameworks/Python.framework/Versions/3.6/lib/python3.6/site-packages/paramiko/pkey.py", line 206, in from_private_key_file
    key = cls(filename=filename, password=password)
  File "/Library/Frameworks/Python.framework/Versions/3.6/lib/python3.6/site-packages/paramiko/rsakey.py", line 55, in __init__
    self._from_private_key_file(filename, password)
  File "/Library/Frameworks/Python.framework/Versions/3.6/lib/python3.6/site-packages/paramiko/rsakey.py", line 175, in _from_private_key_file
    data = self._read_private_key_file("RSA", filename, password)
  File "/Library/Frameworks/Python.framework/Versions/3.6/lib/python3.6/site-packages/paramiko/pkey.py", line 278, in _read_private_key_file
    with open(filename, "r") as f:
FileNotFoundError: [Errno 2] No such file or directory: '/root/.ssh/id_rsa'

2019-07-29 11:51:31,735  - ERROR :  172.16.111.131 BasicPlugin Error:Traceback (most recent call last):
  File "/Users/yky/PycharmProjects/cmdb_db/AutoClient/src/plugins/basic.py", line 47, in linux
    'os_platform': self.os_platform(),
  File "/Users/yky/PycharmProjects/cmdb_db/AutoClient/src/plugins/basic.py", line 17, in os_platform
    output = self.exec_shell_cmd('uname')
  File "/Users/yky/PycharmProjects/cmdb_db/AutoClient/src/plugins/base.py", line 45, in exec_shell_cmd
    output = func(cmd)
  File "/Users/yky/PycharmProjects/cmdb_db/AutoClient/src/plugins/base.py", line 26, in ssh
    private_key = paramiko.RSAKey.from_private_key_file(settings.SSH_PRIVATE_KEY)
  File "/Library/Frameworks/Python.framework/Versions/3.6/lib/python3.6/site-packages/paramiko/pkey.py", line 206, in from_private_key_file
    key = cls(filename=filename, password=password)
  File "/Library/Frameworks/Python.framework/Versions/3.6/lib/python3.6/site-packages/paramiko/rsakey.py", line 55, in __init__
    self._from_private_key_file(filename, password)
  File "/Library/Frameworks/Python.framework/Versions/3.6/lib/python3.6/site-packages/paramiko/rsakey.py", line 175, in _from_private_key_file
    data = self._read_private_key_file("RSA", filename, password)
  File "/Library/Frameworks/Python.framework/Versions/3.6/lib/python3.6/site-packages/paramiko/pkey.py", line 278, in _read_private_key_file
    with open(filename, "r") as f:
FileNotFoundError: [Errno 2] No such file or directory: '/root/.ssh/id_rsa'

2019-07-29 11:51:31,736  - ERROR :  172.16.111.131 BasicPlugin Error:Traceback (most recent call last):
  File "/Users/yky/PycharmProjects/cmdb_db/AutoClient/src/plugins/basic.py", line 47, in linux
    'os_platform': self.os_platform(),
  File "/Users/yky/PycharmProjects/cmdb_db/AutoClient/src/plugins/basic.py", line 17, in os_platform
    output = self.exec_shell_cmd('uname')
  File "/Users/yky/PycharmProjects/cmdb_db/AutoClient/src/plugins/base.py", line 45, in exec_shell_cmd
    output = func(cmd)
  File "/Users/yky/PycharmProjects/cmdb_db/AutoClient/src/plugins/base.py", line 26, in ssh
    private_key = paramiko.RSAKey.from_private_key_file(settings.SSH_PRIVATE_KEY)
  File "/Library/Frameworks/Python.framework/Versions/3.6/lib/python3.6/site-packages/paramiko/pkey.py", line 206, in from_private_key_file
    key = cls(filename=filename, password=password)
  File "/Library/Frameworks/Python.framework/Versions/3.6/lib/python3.6/site-packages/paramiko/rsakey.py", line 55, in __init__
    self._from_private_key_file(filename, password)
  File "/Library/Frameworks/Python.framework/Versions/3.6/lib/python3.6/site-packages/paramiko/rsakey.py", line 175, in _from_private_key_file
    data = self._read_private_key_file("RSA", filename, password)
  File "/Library/Frameworks/Python.framework/Versions/3.6/lib/python3.6/site-packages/paramiko/pkey.py", line 278, in _read_private_key_file
    with open(filename, "r") as f:
FileNotFoundError: [Errno 2] No such file or directory: '/root/.ssh/id_rsa'

2019-07-29 11:53:51,128  - ERROR :  172.16.111.131 BasicPlugin Error:Traceback (most recent call last):
  File "/Users/yky/PycharmProjects/cmdb_db/AutoClient/src/plugins/basic.py", line 47, in linux
    'os_platform': self.os_platform(),
  File "/Users/yky/PycharmProjects/cmdb_db/AutoClient/src/plugins/basic.py", line 17, in os_platform
    output = self.exec_shell_cmd('uname')
  File "/Users/yky/PycharmProjects/cmdb_db/AutoClient/src/plugins/base.py", line 45, in exec_shell_cmd
    output = func(cmd)
  File "/Users/yky/PycharmProjects/cmdb_db/AutoClient/src/plugins/base.py", line 26, in ssh
    private_key = paramiko.RSAKey.from_private_key_file(settings.SSH_PRIVATE_KEY)
  File "/Library/Frameworks/Python.framework/Versions/3.6/lib/python3.6/site-packages/paramiko/pkey.py", line 206, in from_private_key_file
    key = cls(filename=filename, password=password)
  File "/Library/Frameworks/Python.framework/Versions/3.6/lib/python3.6/site-packages/paramiko/rsakey.py", line 55, in __init__
    self._from_private_key_file(filename, password)
  File "/Library/Frameworks/Python.framework/Versions/3.6/lib/python3.6/site-packages/paramiko/rsakey.py", line 175, in _from_private_key_file
    data = self._read_private_key_file("RSA", filename, password)
  File "/Library/Frameworks/Python.framework/Versions/3.6/lib/python3.6/site-packages/paramiko/pkey.py", line 278, in _read_private_key_file
    with open(filename, "r") as f:
FileNotFoundError: [Errno 2] No such file or directory: '/root/.ssh/id_rsa'

2019-07-29 11:53:51,128  - ERROR :  172.16.111.131 BasicPlugin Error:Traceback (most recent call last):
  File "/Users/yky/PycharmProjects/cmdb_db/AutoClient/src/plugins/basic.py", line 47, in linux
    'os_platform': self.os_platform(),
  File "/Users/yky/PycharmProjects/cmdb_db/AutoClient/src/plugins/basic.py", line 17, in os_platform
    output = self.exec_shell_cmd('uname')
  File "/Users/yky/PycharmProjects/cmdb_db/AutoClient/src/plugins/base.py", line 45, in exec_shell_cmd
    output = func(cmd)
  File "/Users/yky/PycharmProjects/cmdb_db/AutoClient/src/plugins/base.py", line 26, in ssh
    private_key = paramiko.RSAKey.from_private_key_file(settings.SSH_PRIVATE_KEY)
  File "/Library/Frameworks/Python.framework/Versions/3.6/lib/python3.6/site-packages/paramiko/pkey.py", line 206, in from_private_key_file
    key = cls(filename=filename, password=password)
  File "/Library/Frameworks/Python.framework/Versions/3.6/lib/python3.6/site-packages/paramiko/rsakey.py", line 55, in __init__
    self._from_private_key_file(filename, password)
  File "/Library/Frameworks/Python.framework/Versions/3.6/lib/python3.6/site-packages/paramiko/rsakey.py", line 175, in _from_private_key_file
    data = self._read_private_key_file("RSA", filename, password)
  File "/Library/Frameworks/Python.framework/Versions/3.6/lib/python3.6/site-packages/paramiko/pkey.py", line 278, in _read_private_key_file
    with open(filename, "r") as f:
FileNotFoundError: [Errno 2] No such file or directory: '/root/.ssh/id_rsa'

2019-07-29 11:55:34,161  - ERROR :  172.16.111.131 BasicPlugin Error:Traceback (most recent call last):
  File "/Users/yky/PycharmProjects/cmdb_db/AutoClient/src/plugins/basic.py", line 47, in linux
    'os_platform': self.os_platform(),
  File "/Users/yky/PycharmProjects/cmdb_db/AutoClient/src/plugins/basic.py", line 17, in os_platform
    output = self.exec_shell_cmd('uname')
  File "/Users/yky/PycharmProjects/cmdb_db/AutoClient/src/plugins/base.py", line 45, in exec_shell_cmd
    output = func(cmd)
  File "/Users/yky/PycharmProjects/cmdb_db/AutoClient/src/plugins/base.py", line 26, in ssh
    private_key = paramiko.RSAKey.from_private_key_file(settings.SSH_PRIVATE_KEY)
  File "/Library/Frameworks/Python.framework/Versions/3.6/lib/python3.6/site-packages/paramiko/pkey.py", line 206, in from_private_key_file
    key = cls(filename=filename, password=password)
  File "/Library/Frameworks/Python.framework/Versions/3.6/lib/python3.6/site-packages/paramiko/rsakey.py", line 55, in __init__
    self._from_private_key_file(filename, password)
  File "/Library/Frameworks/Python.framework/Versions/3.6/lib/python3.6/site-packages/paramiko/rsakey.py", line 175, in _from_private_key_file
    data = self._read_private_key_file("RSA", filename, password)
  File "/Library/Frameworks/Python.framework/Versions/3.6/lib/python3.6/site-packages/paramiko/pkey.py", line 278, in _read_private_key_file
    with open(filename, "r") as f:
FileNotFoundError: [Errno 2] No such file or directory: '/root/.ssh/id_rsa'

2019-07-29 11:55:34,162  - ERROR :  172.16.111.131 BasicPlugin Error:Traceback (most recent call last):
  File "/Users/yky/PycharmProjects/cmdb_db/AutoClient/src/plugins/basic.py", line 47, in linux
    'os_platform': self.os_platform(),
  File "/Users/yky/PycharmProjects/cmdb_db/AutoClient/src/plugins/basic.py", line 17, in os_platform
    output = self.exec_shell_cmd('uname')
  File "/Users/yky/PycharmProjects/cmdb_db/AutoClient/src/plugins/base.py", line 45, in exec_shell_cmd
    output = func(cmd)
  File "/Users/yky/PycharmProjects/cmdb_db/AutoClient/src/plugins/base.py", line 26, in ssh
    private_key = paramiko.RSAKey.from_private_key_file(settings.SSH_PRIVATE_KEY)
  File "/Library/Frameworks/Python.framework/Versions/3.6/lib/python3.6/site-packages/paramiko/pkey.py", line 206, in from_private_key_file
    key = cls(filename=filename, password=password)
  File "/Library/Frameworks/Python.framework/Versions/3.6/lib/python3.6/site-packages/paramiko/rsakey.py", line 55, in __init__
    self._from_private_key_file(filename, password)
  File "/Library/Frameworks/Python.framework/Versions/3.6/lib/python3.6/site-packages/paramiko/rsakey.py", line 175, in _from_private_key_file
    data = self._read_private_key_file("RSA", filename, password)
  File "/Library/Frameworks/Python.framework/Versions/3.6/lib/python3.6/site-packages/paramiko/pkey.py", line 278, in _read_private_key_file
    with open(filename, "r") as f:
FileNotFoundError: [Errno 2] No such file or directory: '/root/.ssh/id_rsa'

2019-07-29 11:57:00,618  - ERROR :  172.16.111.131 BasicPlugin Error:Traceback (most recent call last):
  File "/Users/yky/PycharmProjects/cmdb_db/AutoClient/src/plugins/basic.py", line 47, in linux
    'os_platform': self.os_platform(),
  File "/Users/yky/PycharmProjects/cmdb_db/AutoClient/src/plugins/basic.py", line 17, in os_platform
    output = self.exec_shell_cmd('uname')
  File "/Users/yky/PycharmProjects/cmdb_db/AutoClient/src/plugins/base.py", line 45, in exec_shell_cmd
    output = func(cmd)
  File "/Users/yky/PycharmProjects/cmdb_db/AutoClient/src/plugins/base.py", line 26, in ssh
    private_key = paramiko.RSAKey.from_private_key_file(settings.SSH_PRIVATE_KEY)
  File "/Library/Frameworks/Python.framework/Versions/3.6/lib/python3.6/site-packages/paramiko/pkey.py", line 206, in from_private_key_file
    key = cls(filename=filename, password=password)
  File "/Library/Frameworks/Python.framework/Versions/3.6/lib/python3.6/site-packages/paramiko/rsakey.py", line 55, in __init__
    self._from_private_key_file(filename, password)
  File "/Library/Frameworks/Python.framework/Versions/3.6/lib/python3.6/site-packages/paramiko/rsakey.py", line 175, in _from_private_key_file
    data = self._read_private_key_file("RSA", filename, password)
  File "/Library/Frameworks/Python.framework/Versions/3.6/lib/python3.6/site-packages/paramiko/pkey.py", line 278, in _read_private_key_file
    with open(filename, "r") as f:
FileNotFoundError: [Errno 2] No such file or directory: '/root/.ssh/id_rsa'

2019-07-29 11:57:00,620  - ERROR :  172.16.111.131 BasicPlugin Error:Traceback (most recent call last):
  File "/Users/yky/PycharmProjects/cmdb_db/AutoClient/src/plugins/basic.py", line 47, in linux
    'os_platform': self.os_platform(),
  File "/Users/yky/PycharmProjects/cmdb_db/AutoClient/src/plugins/basic.py", line 17, in os_platform
    output = self.exec_shell_cmd('uname')
  File "/Users/yky/PycharmProjects/cmdb_db/AutoClient/src/plugins/base.py", line 45, in exec_shell_cmd
    output = func(cmd)
  File "/Users/yky/PycharmProjects/cmdb_db/AutoClient/src/plugins/base.py", line 26, in ssh
    private_key = paramiko.RSAKey.from_private_key_file(settings.SSH_PRIVATE_KEY)
  File "/Library/Frameworks/Python.framework/Versions/3.6/lib/python3.6/site-packages/paramiko/pkey.py", line 206, in from_private_key_file
    key = cls(filename=filename, password=password)
  File "/Library/Frameworks/Python.framework/Versions/3.6/lib/python3.6/site-packages/paramiko/rsakey.py", line 55, in __init__
    self._from_private_key_file(filename, password)
  File "/Library/Frameworks/Python.framework/Versions/3.6/lib/python3.6/site-packages/paramiko/rsakey.py", line 175, in _from_private_key_file
    data = self._read_private_key_file("RSA", filename, password)
  File "/Library/Frameworks/Python.framework/Versions/3.6/lib/python3.6/site-packages/paramiko/pkey.py", line 278, in _read_private_key_file
    with open(filename, "r") as f:
FileNotFoundError: [Errno 2] No such file or directory: '/root/.ssh/id_rsa'

2019-07-29 11:58:15,309  - ERROR :  172.16.111.131 BasicPlugin Error:Traceback (most recent call last):
  File "/Users/yky/PycharmProjects/cmdb_db/AutoClient/src/plugins/basic.py", line 47, in linux
    'os_platform': self.os_platform(),
  File "/Users/yky/PycharmProjects/cmdb_db/AutoClient/src/plugins/basic.py", line 17, in os_platform
    output = self.exec_shell_cmd('uname')
  File "/Users/yky/PycharmProjects/cmdb_db/AutoClient/src/plugins/base.py", line 45, in exec_shell_cmd
    output = func(cmd)
  File "/Users/yky/PycharmProjects/cmdb_db/AutoClient/src/plugins/base.py", line 26, in ssh
    private_key = paramiko.RSAKey.from_private_key_file(settings.SSH_PRIVATE_KEY)
  File "/Library/Frameworks/Python.framework/Versions/3.6/lib/python3.6/site-packages/paramiko/pkey.py", line 206, in from_private_key_file
    key = cls(filename=filename, password=password)
  File "/Library/Frameworks/Python.framework/Versions/3.6/lib/python3.6/site-packages/paramiko/rsakey.py", line 55, in __init__
    self._from_private_key_file(filename, password)
  File "/Library/Frameworks/Python.framework/Versions/3.6/lib/python3.6/site-packages/paramiko/rsakey.py", line 175, in _from_private_key_file
    data = self._read_private_key_file("RSA", filename, password)
  File "/Library/Frameworks/Python.framework/Versions/3.6/lib/python3.6/site-packages/paramiko/pkey.py", line 278, in _read_private_key_file
    with open(filename, "r") as f:
FileNotFoundError: [Errno 2] No such file or directory: '/root/.ssh/id_rsa'

2019-07-29 11:58:15,309  - ERROR :  172.16.111.131 BasicPlugin Error:Traceback (most recent call last):
  File "/Users/yky/PycharmProjects/cmdb_db/AutoClient/src/plugins/basic.py", line 47, in linux
    'os_platform': self.os_platform(),
  File "/Users/yky/PycharmProjects/cmdb_db/AutoClient/src/plugins/basic.py", line 17, in os_platform
    output = self.exec_shell_cmd('uname')
  File "/Users/yky/PycharmProjects/cmdb_db/AutoClient/src/plugins/base.py", line 45, in exec_shell_cmd
    output = func(cmd)
  File "/Users/yky/PycharmProjects/cmdb_db/AutoClient/src/plugins/base.py", line 26, in ssh
    private_key = paramiko.RSAKey.from_private_key_file(settings.SSH_PRIVATE_KEY)
  File "/Library/Frameworks/Python.framework/Versions/3.6/lib/python3.6/site-packages/paramiko/pkey.py", line 206, in from_private_key_file
    key = cls(filename=filename, password=password)
  File "/Library/Frameworks/Python.framework/Versions/3.6/lib/python3.6/site-packages/paramiko/rsakey.py", line 55, in __init__
    self._from_private_key_file(filename, password)
  File "/Library/Frameworks/Python.framework/Versions/3.6/lib/python3.6/site-packages/paramiko/rsakey.py", line 175, in _from_private_key_file
    data = self._read_private_key_file("RSA", filename, password)
  File "/Library/Frameworks/Python.framework/Versions/3.6/lib/python3.6/site-packages/paramiko/pkey.py", line 278, in _read_private_key_file
    with open(filename, "r") as f:
FileNotFoundError: [Errno 2] No such file or directory: '/root/.ssh/id_rsa'

2019-07-29 12:59:13,381  - ERROR :  172.16.111.131 BasicPlugin Error:Traceback (most recent call last):
  File "/Users/yky/PycharmProjects/cmdb_db/AutoClient/src/plugins/basic.py", line 47, in linux
    'os_platform': self.os_platform(),
  File "/Users/yky/PycharmProjects/cmdb_db/AutoClient/src/plugins/basic.py", line 17, in os_platform
    output = self.exec_shell_cmd('uname')
  File "/Users/yky/PycharmProjects/cmdb_db/AutoClient/src/plugins/base.py", line 45, in exec_shell_cmd
    output = func(cmd)
  File "/Users/yky/PycharmProjects/cmdb_db/AutoClient/src/plugins/base.py", line 26, in ssh
    private_key = paramiko.RSAKey.from_private_key_file(settings.SSH_PRIVATE_KEY)
  File "/Library/Frameworks/Python.framework/Versions/3.6/lib/python3.6/site-packages/paramiko/pkey.py", line 206, in from_private_key_file
    key = cls(filename=filename, password=password)
  File "/Library/Frameworks/Python.framework/Versions/3.6/lib/python3.6/site-packages/paramiko/rsakey.py", line 55, in __init__
    self._from_private_key_file(filename, password)
  File "/Library/Frameworks/Python.framework/Versions/3.6/lib/python3.6/site-packages/paramiko/rsakey.py", line 175, in _from_private_key_file
    data = self._read_private_key_file("RSA", filename, password)
  File "/Library/Frameworks/Python.framework/Versions/3.6/lib/python3.6/site-packages/paramiko/pkey.py", line 278, in _read_private_key_file
    with open(filename, "r") as f:
FileNotFoundError: [Errno 2] No such file or directory: '/root/.ssh/id_rsa'

2019-07-29 12:59:13,382  - ERROR :  172.16.111.131 BasicPlugin Error:Traceback (most recent call last):
  File "/Users/yky/PycharmProjects/cmdb_db/AutoClient/src/plugins/basic.py", line 47, in linux
    'os_platform': self.os_platform(),
  File "/Users/yky/PycharmProjects/cmdb_db/AutoClient/src/plugins/basic.py", line 17, in os_platform
    output = self.exec_shell_cmd('uname')
  File "/Users/yky/PycharmProjects/cmdb_db/AutoClient/src/plugins/base.py", line 45, in exec_shell_cmd
    output = func(cmd)
  File "/Users/yky/PycharmProjects/cmdb_db/AutoClient/src/plugins/base.py", line 26, in ssh
    private_key = paramiko.RSAKey.from_private_key_file(settings.SSH_PRIVATE_KEY)
  File "/Library/Frameworks/Python.framework/Versions/3.6/lib/python3.6/site-packages/paramiko/pkey.py", line 206, in from_private_key_file
    key = cls(filename=filename, password=password)
  File "/Library/Frameworks/Python.framework/Versions/3.6/lib/python3.6/site-packages/paramiko/rsakey.py", line 55, in __init__
    self._from_private_key_file(filename, password)
  File "/Library/Frameworks/Python.framework/Versions/3.6/lib/python3.6/site-packages/paramiko/rsakey.py", line 175, in _from_private_key_file
    data = self._read_private_key_file("RSA", filename, password)
  File "/Library/Frameworks/Python.framework/Versions/3.6/lib/python3.6/site-packages/paramiko/pkey.py", line 278, in _read_private_key_file
    with open(filename, "r") as f:
FileNotFoundError: [Errno 2] No such file or directory: '/root/.ssh/id_rsa'

2019-07-29 13:03:28,306  - ERROR :  172.16.111.131 BasicPlugin Error:Traceback (most recent call last):
  File "/Users/yky/PycharmProjects/cmdb_db/AutoClient/src/plugins/basic.py", line 47, in linux
    'os_platform': self.os_platform(),
  File "/Users/yky/PycharmProjects/cmdb_db/AutoClient/src/plugins/basic.py", line 17, in os_platform
    output = self.exec_shell_cmd('uname')
  File "/Users/yky/PycharmProjects/cmdb_db/AutoClient/src/plugins/base.py", line 45, in exec_shell_cmd
    output = func(cmd)
  File "/Users/yky/PycharmProjects/cmdb_db/AutoClient/src/plugins/base.py", line 26, in ssh
    private_key = paramiko.RSAKey.from_private_key_file(settings.SSH_PRIVATE_KEY)
  File "/Library/Frameworks/Python.framework/Versions/3.6/lib/python3.6/site-packages/paramiko/pkey.py", line 206, in from_private_key_file
    key = cls(filename=filename, password=password)
  File "/Library/Frameworks/Python.framework/Versions/3.6/lib/python3.6/site-packages/paramiko/rsakey.py", line 55, in __init__
    self._from_private_key_file(filename, password)
  File "/Library/Frameworks/Python.framework/Versions/3.6/lib/python3.6/site-packages/paramiko/rsakey.py", line 175, in _from_private_key_file
    data = self._read_private_key_file("RSA", filename, password)
  File "/Library/Frameworks/Python.framework/Versions/3.6/lib/python3.6/site-packages/paramiko/pkey.py", line 278, in _read_private_key_file
    with open(filename, "r") as f:
FileNotFoundError: [Errno 2] No such file or directory: '/root/.ssh/id_rsa'

2019-07-29 13:03:28,306  - ERROR :  172.16.111.131 BasicPlugin Error:Traceback (most recent call last):
  File "/Users/yky/PycharmProjects/cmdb_db/AutoClient/src/plugins/basic.py", line 47, in linux
    'os_platform': self.os_platform(),
  File "/Users/yky/PycharmProjects/cmdb_db/AutoClient/src/plugins/basic.py", line 17, in os_platform
    output = self.exec_shell_cmd('uname')
  File "/Users/yky/PycharmProjects/cmdb_db/AutoClient/src/plugins/base.py", line 45, in exec_shell_cmd
    output = func(cmd)
  File "/Users/yky/PycharmProjects/cmdb_db/AutoClient/src/plugins/base.py", line 26, in ssh
    private_key = paramiko.RSAKey.from_private_key_file(settings.SSH_PRIVATE_KEY)
  File "/Library/Frameworks/Python.framework/Versions/3.6/lib/python3.6/site-packages/paramiko/pkey.py", line 206, in from_private_key_file
    key = cls(filename=filename, password=password)
  File "/Library/Frameworks/Python.framework/Versions/3.6/lib/python3.6/site-packages/paramiko/rsakey.py", line 55, in __init__
    self._from_private_key_file(filename, password)
  File "/Library/Frameworks/Python.framework/Versions/3.6/lib/python3.6/site-packages/paramiko/rsakey.py", line 175, in _from_private_key_file
    data = self._read_private_key_file("RSA", filename, password)
  File "/Library/Frameworks/Python.framework/Versions/3.6/lib/python3.6/site-packages/paramiko/pkey.py", line 278, in _read_private_key_file
    with open(filename, "r") as f:
FileNotFoundError: [Errno 2] No such file or directory: '/root/.ssh/id_rsa'

2019-07-29 14:41:10,384  - ERROR :  None BasicPlugin Error:Traceback (most recent call last):
  File "/Users/yky/PycharmProjects/cmdb_db/AutoClient/src/plugins/basic.py", line 47, in linux
    'os_platform': self.os_platform(),
  File "/Users/yky/PycharmProjects/cmdb_db/AutoClient/src/plugins/basic.py", line 17, in os_platform
    output = self.exec_shell_cmd('uname')
  File "/Users/yky/PycharmProjects/cmdb_db/AutoClient/src/plugins/base.py", line 45, in exec_shell_cmd
    output = func(cmd)
  File "/Users/yky/PycharmProjects/cmdb_db/AutoClient/src/plugins/base.py", line 26, in ssh
    private_key = paramiko.RSAKey.from_private_key_file(settings.SSH_PRIVATE_KEY)
  File "/Library/Frameworks/Python.framework/Versions/3.6/lib/python3.6/site-packages/paramiko/pkey.py", line 206, in from_private_key_file
    key = cls(filename=filename, password=password)
  File "/Library/Frameworks/Python.framework/Versions/3.6/lib/python3.6/site-packages/paramiko/rsakey.py", line 55, in __init__
    self._from_private_key_file(filename, password)
  File "/Library/Frameworks/Python.framework/Versions/3.6/lib/python3.6/site-packages/paramiko/rsakey.py", line 175, in _from_private_key_file
    data = self._read_private_key_file("RSA", filename, password)
  File "/Library/Frameworks/Python.framework/Versions/3.6/lib/python3.6/site-packages/paramiko/pkey.py", line 278, in _read_private_key_file
    with open(filename, "r") as f:
FileNotFoundError: [Errno 2] No such file or directory: '/root/.ssh/id_rsa'

2019-07-29 14:44:26,388  - ERROR :  None BasicPlugin Error:Traceback (most recent call last):
  File "/Users/yky/PycharmProjects/cmdb_db/AutoClient/src/plugins/basic.py", line 47, in linux
    'os_platform': self.os_platform(),
  File "/Users/yky/PycharmProjects/cmdb_db/AutoClient/src/plugins/basic.py", line 17, in os_platform
    output = self.exec_shell_cmd('uname')
  File "/Users/yky/PycharmProjects/cmdb_db/AutoClient/src/plugins/base.py", line 45, in exec_shell_cmd
    output = func(cmd)
  File "/Users/yky/PycharmProjects/cmdb_db/AutoClient/src/plugins/base.py", line 26, in ssh
    private_key = paramiko.RSAKey.from_private_key_file(settings.SSH_PRIVATE_KEY)
  File "/Library/Frameworks/Python.framework/Versions/3.6/lib/python3.6/site-packages/paramiko/pkey.py", line 206, in from_private_key_file
    key = cls(filename=filename, password=password)
  File "/Library/Frameworks/Python.framework/Versions/3.6/lib/python3.6/site-packages/paramiko/rsakey.py", line 55, in __init__
    self._from_private_key_file(filename, password)
  File "/Library/Frameworks/Python.framework/Versions/3.6/lib/python3.6/site-packages/paramiko/rsakey.py", line 175, in _from_private_key_file
    data = self._read_private_key_file("RSA", filename, password)
  File "/Library/Frameworks/Python.framework/Versions/3.6/lib/python3.6/site-packages/paramiko/pkey.py", line 278, in _read_private_key_file
    with open(filename, "r") as f:
FileNotFoundError: [Errno 2] No such file or directory: '/root/.ssh/id_rsa'

2019-07-29 15:03:05,322  - ERROR :  None BasicPlugin Error:Traceback (most recent call last):
  File "/Users/yky/PycharmProjects/cmdb_db/AutoClient/src/plugins/basic.py", line 47, in linux
    'os_platform': self.os_platform(),
  File "/Users/yky/PycharmProjects/cmdb_db/AutoClient/src/plugins/basic.py", line 17, in os_platform
    output = self.exec_shell_cmd('uname')
  File "/Users/yky/PycharmProjects/cmdb_db/AutoClient/src/plugins/base.py", line 45, in exec_shell_cmd
    output = func(cmd)
  File "/Users/yky/PycharmProjects/cmdb_db/AutoClient/src/plugins/base.py", line 26, in ssh
    private_key = paramiko.RSAKey.from_private_key_file(settings.SSH_PRIVATE_KEY)
  File "/Library/Frameworks/Python.framework/Versions/3.6/lib/python3.6/site-packages/paramiko/pkey.py", line 206, in from_private_key_file
    key = cls(filename=filename, password=password)
  File "/Library/Frameworks/Python.framework/Versions/3.6/lib/python3.6/site-packages/paramiko/rsakey.py", line 55, in __init__
    self._from_private_key_file(filename, password)
  File "/Library/Frameworks/Python.framework/Versions/3.6/lib/python3.6/site-packages/paramiko/rsakey.py", line 175, in _from_private_key_file
    data = self._read_private_key_file("RSA", filename, password)
  File "/Library/Frameworks/Python.framework/Versions/3.6/lib/python3.6/site-packages/paramiko/pkey.py", line 278, in _read_private_key_file
    with open(filename, "r") as f:
FileNotFoundError: [Errno 2] No such file or directory: '/root/.ssh/id_rsa'

2019-07-29 15:03:21,460  - ERROR :  None BasicPlugin Error:Traceback (most recent call last):
  File "/Users/yky/PycharmProjects/cmdb_db/AutoClient/src/plugins/basic.py", line 47, in linux
    'os_platform': self.os_platform(),
  File "/Users/yky/PycharmProjects/cmdb_db/AutoClient/src/plugins/basic.py", line 17, in os_platform
    output = self.exec_shell_cmd('uname')
  File "/Users/yky/PycharmProjects/cmdb_db/AutoClient/src/plugins/base.py", line 45, in exec_shell_cmd
    output = func(cmd)
  File "/Users/yky/PycharmProjects/cmdb_db/AutoClient/src/plugins/base.py", line 26, in ssh
    private_key = paramiko.RSAKey.from_private_key_file(settings.SSH_PRIVATE_KEY)
  File "/Library/Frameworks/Python.framework/Versions/3.6/lib/python3.6/site-packages/paramiko/pkey.py", line 206, in from_private_key_file
    key = cls(filename=filename, password=password)
  File "/Library/Frameworks/Python.framework/Versions/3.6/lib/python3.6/site-packages/paramiko/rsakey.py", line 55, in __init__
    self._from_private_key_file(filename, password)
  File "/Library/Frameworks/Python.framework/Versions/3.6/lib/python3.6/site-packages/paramiko/rsakey.py", line 175, in _from_private_key_file
    data = self._read_private_key_file("RSA", filename, password)
  File "/Library/Frameworks/Python.framework/Versions/3.6/lib/python3.6/site-packages/paramiko/pkey.py", line 278, in _read_private_key_file
    with open(filename, "r") as f:
FileNotFoundError: [Errno 2] No such file or directory: '/root/.ssh/id_rsa'

2019-07-29 15:31:51,781  - ERROR :  172.16.111.131 BasicPlugin Error:Traceback (most recent call last):
  File "/Users/yky/PycharmProjects/cmdb_db/AutoClient/src/plugins/basic.py", line 47, in linux
    'os_platform': self.os_platform(),
  File "/Users/yky/PycharmProjects/cmdb_db/AutoClient/src/plugins/basic.py", line 17, in os_platform
    output = self.exec_shell_cmd('uname')
  File "/Users/yky/PycharmProjects/cmdb_db/AutoClient/src/plugins/base.py", line 45, in exec_shell_cmd
    output = func(cmd)
  File "/Users/yky/PycharmProjects/cmdb_db/AutoClient/src/plugins/base.py", line 26, in ssh
    private_key = paramiko.RSAKey.from_private_key_file(settings.SSH_PRIVATE_KEY)
  File "/Library/Frameworks/Python.framework/Versions/3.6/lib/python3.6/site-packages/paramiko/pkey.py", line 206, in from_private_key_file
    key = cls(filename=filename, password=password)
  File "/Library/Frameworks/Python.framework/Versions/3.6/lib/python3.6/site-packages/paramiko/rsakey.py", line 55, in __init__
    self._from_private_key_file(filename, password)
  File "/Library/Frameworks/Python.framework/Versions/3.6/lib/python3.6/site-packages/paramiko/rsakey.py", line 175, in _from_private_key_file
    data = self._read_private_key_file("RSA", filename, password)
  File "/Library/Frameworks/Python.framework/Versions/3.6/lib/python3.6/site-packages/paramiko/pkey.py", line 278, in _read_private_key_file
    with open(filename, "r") as f:
FileNotFoundError: [Errno 2] No such file or directory: '/root/.ssh/id_rsa'

2019-07-29 15:31:51,782  - ERROR :  172.16.111.131 BasicPlugin Error:Traceback (most recent call last):
  File "/Users/yky/PycharmProjects/cmdb_db/AutoClient/src/plugins/basic.py", line 47, in linux
    'os_platform': self.os_platform(),
  File "/Users/yky/PycharmProjects/cmdb_db/AutoClient/src/plugins/basic.py", line 17, in os_platform
    output = self.exec_shell_cmd('uname')
  File "/Users/yky/PycharmProjects/cmdb_db/AutoClient/src/plugins/base.py", line 45, in exec_shell_cmd
    output = func(cmd)
  File "/Users/yky/PycharmProjects/cmdb_db/AutoClient/src/plugins/base.py", line 26, in ssh
    private_key = paramiko.RSAKey.from_private_key_file(settings.SSH_PRIVATE_KEY)
  File "/Library/Frameworks/Python.framework/Versions/3.6/lib/python3.6/site-packages/paramiko/pkey.py", line 206, in from_private_key_file
    key = cls(filename=filename, password=password)
  File "/Library/Frameworks/Python.framework/Versions/3.6/lib/python3.6/site-packages/paramiko/rsakey.py", line 55, in __init__
    self._from_private_key_file(filename, password)
  File "/Library/Frameworks/Python.framework/Versions/3.6/lib/python3.6/site-packages/paramiko/rsakey.py", line 175, in _from_private_key_file
    data = self._read_private_key_file("RSA", filename, password)
  File "/Library/Frameworks/Python.framework/Versions/3.6/lib/python3.6/site-packages/paramiko/pkey.py", line 278, in _read_private_key_file
    with open(filename, "r") as f:
FileNotFoundError: [Errno 2] No such file or directory: '/root/.ssh/id_rsa'

2019-07-29 15:33:49,335  - ERROR :  None BasicPlugin Error:Traceback (most recent call last):
  File "/Users/yky/PycharmProjects/cmdb_db/AutoClient/src/plugins/basic.py", line 47, in linux
    'os_platform': self.os_platform(),
  File "/Users/yky/PycharmProjects/cmdb_db/AutoClient/src/plugins/basic.py", line 17, in os_platform
    output = self.exec_shell_cmd('uname')
  File "/Users/yky/PycharmProjects/cmdb_db/AutoClient/src/plugins/base.py", line 45, in exec_shell_cmd
    output = func(cmd)
  File "/Users/yky/PycharmProjects/cmdb_db/AutoClient/src/plugins/base.py", line 26, in ssh
    private_key = paramiko.RSAKey.from_private_key_file(settings.SSH_PRIVATE_KEY)
  File "/Library/Frameworks/Python.framework/Versions/3.6/lib/python3.6/site-packages/paramiko/pkey.py", line 206, in from_private_key_file
    key = cls(filename=filename, password=password)
  File "/Library/Frameworks/Python.framework/Versions/3.6/lib/python3.6/site-packages/paramiko/rsakey.py", line 55, in __init__
    self._from_private_key_file(filename, password)
  File "/Library/Frameworks/Python.framework/Versions/3.6/lib/python3.6/site-packages/paramiko/rsakey.py", line 175, in _from_private_key_file
    data = self._read_private_key_file("RSA", filename, password)
  File "/Library/Frameworks/Python.framework/Versions/3.6/lib/python3.6/site-packages/paramiko/pkey.py", line 278, in _read_private_key_file
    with open(filename, "r") as f:
FileNotFoundError: [Errno 2] No such file or directory: '/root/.ssh/id_rsa'

2019-07-29 15:36:30,224  - ERROR :  [c1.com]资产不存在
2019-07-29 15:36:30,224  - ERROR :  [c1.com]资产不存在
2019-07-29 15:40:39,249  - ERROR :  [c1.com]资产不存在
2019-07-29 15:40:39,253  - ERROR :  [c1.com]资产不存在
2019-07-29 15:40:39,255  - ERROR :  [c1.com]资产不存在
2019-07-29 15:59:59,079  - ERROR :  [c1.com]资产不存在
2019-07-29 15:59:59,081  - ERROR :  [c1.com]资产不存在
2019-07-29 15:59:59,083  - ERROR :  [c1.com]资产不存在
2019-07-29 16:24:42,699  - ERROR :  [c1.com]资产不存在
2019-07-29 16:36:05,687  - ERROR :  [c1.com]资产不存在
2019-07-29 16:37:14,494  - ERROR :  [c1.com]资产不存在
2019-07-29 16:37:28,504  - ERROR :  [c1.com]资产不存在
2019-07-29 16:37:34,589  - ERROR :  [c1.com]资产不存在
2019-07-29 16:39:39,446  - ERROR :  [c1.com]资产不存在
2019-07-29 16:46:25,229  - ERROR :  [c1.com]资产不存在
2019-07-29 16:57:31,100  - ERROR :  [c1.com]资产不存在
2019-07-29 16:57:41,239  - ERROR :  [c1.com]资产不存在
2019-07-29 17:03:39,700  - ERROR :  [c1.com]资产不存在
2019-07-29 17:15:57,207  - ERROR :  172.16.111.131 BasicPlugin Error:Traceback (most recent call last):
  File "/Users/yky/PycharmProjects/cmdb_db/AutoClient/src/plugins/basic.py", line 47, in linux
    'os_platform': self.os_platform(),
  File "/Users/yky/PycharmProjects/cmdb_db/AutoClient/src/plugins/basic.py", line 17, in os_platform
    output = self.exec_shell_cmd('uname')
  File "/Users/yky/PycharmProjects/cmdb_db/AutoClient/src/plugins/base.py", line 45, in exec_shell_cmd
    output = func(cmd)
  File "/Users/yky/PycharmProjects/cmdb_db/AutoClient/src/plugins/base.py", line 26, in ssh
    private_key = paramiko.RSAKey.from_private_key_file(settings.SSH_PRIVATE_KEY)
  File "/Library/Frameworks/Python.framework/Versions/3.6/lib/python3.6/site-packages/paramiko/pkey.py", line 206, in from_private_key_file
    key = cls(filename=filename, password=password)
  File "/Library/Frameworks/Python.framework/Versions/3.6/lib/python3.6/site-packages/paramiko/rsakey.py", line 55, in __init__
    self._from_private_key_file(filename, password)
  File "/Library/Frameworks/Python.framework/Versions/3.6/lib/python3.6/site-packages/paramiko/rsakey.py", line 175, in _from_private_key_file
    data = self._read_private_key_file("RSA", filename, password)
  File "/Library/Frameworks/Python.framework/Versions/3.6/lib/python3.6/site-packages/paramiko/pkey.py", line 278, in _read_private_key_file
    with open(filename, "r") as f:
FileNotFoundError: [Errno 2] No such file or directory: '/root/.ssh/id_rsa'

2019-07-29 17:16:09,249  - ERROR :  172.16.111.131 BasicPlugin Error:Traceback (most recent call last):
  File "/Users/yky/PycharmProjects/cmdb_db/AutoClient/src/plugins/basic.py", line 47, in linux
    'os_platform': self.os_platform(),
  File "/Users/yky/PycharmProjects/cmdb_db/AutoClient/src/plugins/basic.py", line 17, in os_platform
    output = self.exec_shell_cmd('uname')
  File "/Users/yky/PycharmProjects/cmdb_db/AutoClient/src/plugins/base.py", line 45, in exec_shell_cmd
    output = func(cmd)
  File "/Users/yky/PycharmProjects/cmdb_db/AutoClient/src/plugins/base.py", line 26, in ssh
    private_key = paramiko.RSAKey.from_private_key_file(settings.SSH_PRIVATE_KEY)
  File "/Library/Frameworks/Python.framework/Versions/3.6/lib/python3.6/site-packages/paramiko/pkey.py", line 206, in from_private_key_file
    key = cls(filename=filename, password=password)
  File "/Library/Frameworks/Python.framework/Versions/3.6/lib/python3.6/site-packages/paramiko/rsakey.py", line 55, in __init__
    self._from_private_key_file(filename, password)
  File "/Library/Frameworks/Python.framework/Versions/3.6/lib/python3.6/site-packages/paramiko/rsakey.py", line 175, in _from_private_key_file
    data = self._read_private_key_file("RSA", filename, password)
  File "/Library/Frameworks/Python.framework/Versions/3.6/lib/python3.6/site-packages/paramiko/pkey.py", line 278, in _read_private_key_file
    with open(filename, "r") as f:
FileNotFoundError: [Errno 2] No such file or directory: '/root/.ssh/id_rsa'

2019-07-29 17:19:15,140  - ERROR :  172.16.111.131 BasicPlugin Error:Traceback (most recent call last):
  File "/Users/yky/PycharmProjects/cmdb_db/AutoClient/src/plugins/basic.py", line 47, in linux
    'os_platform': self.os_platform(),
  File "/Users/yky/PycharmProjects/cmdb_db/AutoClient/src/plugins/basic.py", line 17, in os_platform
    output = self.exec_shell_cmd('uname')
  File "/Users/yky/PycharmProjects/cmdb_db/AutoClient/src/plugins/base.py", line 45, in exec_shell_cmd
    output = func(cmd)
  File "/Users/yky/PycharmProjects/cmdb_db/AutoClient/src/plugins/base.py", line 26, in ssh
    private_key = paramiko.RSAKey.from_private_key_file(settings.SSH_PRIVATE_KEY)
  File "/Library/Frameworks/Python.framework/Versions/3.6/lib/python3.6/site-packages/paramiko/pkey.py", line 206, in from_private_key_file
    key = cls(filename=filename, password=password)
  File "/Library/Frameworks/Python.framework/Versions/3.6/lib/python3.6/site-packages/paramiko/rsakey.py", line 55, in __init__
    self._from_private_key_file(filename, password)
  File "/Library/Frameworks/Python.framework/Versions/3.6/lib/python3.6/site-packages/paramiko/rsakey.py", line 175, in _from_private_key_file
    data = self._read_private_key_file("RSA", filename, password)
  File "/Library/Frameworks/Python.framework/Versions/3.6/lib/python3.6/site-packages/paramiko/pkey.py", line 278, in _read_private_key_file
    with open(filename, "r") as f:
FileNotFoundError: [Errno 2] No such file or directory: '/root/.ssh/id_rsa'

2019-07-29 17:19:50,760  - ERROR :  172.16.111.131 BasicPlugin Error:Traceback (most recent call last):
  File "/Users/yky/PycharmProjects/cmdb_db/AutoClient/src/plugins/basic.py", line 47, in linux
    'os_platform': self.os_platform(),
  File "/Users/yky/PycharmProjects/cmdb_db/AutoClient/src/plugins/basic.py", line 17, in os_platform
    output = self.exec_shell_cmd('uname')
  File "/Users/yky/PycharmProjects/cmdb_db/AutoClient/src/plugins/base.py", line 45, in exec_shell_cmd
    output = func(cmd)
  File "/Users/yky/PycharmProjects/cmdb_db/AutoClient/src/plugins/base.py", line 26, in ssh
    private_key = paramiko.RSAKey.from_private_key_file(settings.SSH_PRIVATE_KEY)
  File "/Library/Frameworks/Python.framework/Versions/3.6/lib/python3.6/site-packages/paramiko/pkey.py", line 206, in from_private_key_file
    key = cls(filename=filename, password=password)
  File "/Library/Frameworks/Python.framework/Versions/3.6/lib/python3.6/site-packages/paramiko/rsakey.py", line 55, in __init__
    self._from_private_key_file(filename, password)
  File "/Library/Frameworks/Python.framework/Versions/3.6/lib/python3.6/site-packages/paramiko/rsakey.py", line 175, in _from_private_key_file
    data = self._read_private_key_file("RSA", filename, password)
  File "/Library/Frameworks/Python.framework/Versions/3.6/lib/python3.6/site-packages/paramiko/pkey.py", line 278, in _read_private_key_file
    with open(filename, "r") as f:
FileNotFoundError: [Errno 2] No such file or directory: '/root/.ssh/id_rsa'

2019-07-29 17:21:57,096  - ERROR :  172.16.111.131 BasicPlugin Error:Traceback (most recent call last):
  File "/Users/yky/PycharmProjects/cmdb_db/AutoClient/src/plugins/basic.py", line 47, in linux
    'os_platform': self.os_platform(),
  File "/Users/yky/PycharmProjects/cmdb_db/AutoClient/src/plugins/basic.py", line 17, in os_platform
    output = self.exec_shell_cmd('uname')
  File "/Users/yky/PycharmProjects/cmdb_db/AutoClient/src/plugins/base.py", line 45, in exec_shell_cmd
    output = func(cmd)
  File "/Users/yky/PycharmProjects/cmdb_db/AutoClient/src/plugins/base.py", line 26, in ssh
    private_key = paramiko.RSAKey.from_private_key_file(settings.SSH_PRIVATE_KEY)
  File "/Library/Frameworks/Python.framework/Versions/3.6/lib/python3.6/site-packages/paramiko/pkey.py", line 206, in from_private_key_file
    key = cls(filename=filename, password=password)
  File "/Library/Frameworks/Python.framework/Versions/3.6/lib/python3.6/site-packages/paramiko/rsakey.py", line 55, in __init__
    self._from_private_key_file(filename, password)
  File "/Library/Frameworks/Python.framework/Versions/3.6/lib/python3.6/site-packages/paramiko/rsakey.py", line 175, in _from_private_key_file
    data = self._read_private_key_file("RSA", filename, password)
  File "/Library/Frameworks/Python.framework/Versions/3.6/lib/python3.6/site-packages/paramiko/pkey.py", line 278, in _read_private_key_file
    with open(filename, "r") as f:
FileNotFoundError: [Errno 2] No such file or directory: '/root/.ssh/id_rsa'

2019-07-29 17:38:10,396  - ERROR :  [c1.com]资产不存在
2019-07-29 17:38:40,097  - ERROR :  [c1.com]资产不存在
2019-07-29 19:03:53,369  - ERROR :  172.16.111.131 BasicPlugin Error:Traceback (most recent call last):
  File "/Users/yky/PycharmProjects/cmdb_db/AutoClient/src/plugins/basic.py", line 49, in linux
    'os_version': self.os_version(),
  File "/Users/yky/PycharmProjects/cmdb_db/AutoClient/src/plugins/basic.py", line 29, in os_version
    output = self.exec_shell_cmd('cat /etc/issue')
  File "/Users/yky/PycharmProjects/cmdb_db/AutoClient/src/plugins/base.py", line 45, in exec_shell_cmd
    output = func(cmd)
  File "/Users/yky/PycharmProjects/cmdb_db/AutoClient/src/plugins/base.py", line 26, in ssh
    private_key = paramiko.RSAKey.from_private_key_file(settings.SSH_PRIVATE_KEY)
  File "/Library/Frameworks/Python.framework/Versions/3.6/lib/python3.6/site-packages/paramiko/pkey.py", line 206, in from_private_key_file
    key = cls(filename=filename, password=password)
  File "/Library/Frameworks/Python.framework/Versions/3.6/lib/python3.6/site-packages/paramiko/rsakey.py", line 55, in __init__
    self._from_private_key_file(filename, password)
  File "/Library/Frameworks/Python.framework/Versions/3.6/lib/python3.6/site-packages/paramiko/rsakey.py", line 175, in _from_private_key_file
    data = self._read_private_key_file("RSA", filename, password)
  File "/Library/Frameworks/Python.framework/Versions/3.6/lib/python3.6/site-packages/paramiko/pkey.py", line 278, in _read_private_key_file
    with open(filename, "r") as f:
FileNotFoundError: [Errno 2] No such file or directory: '/root/.ssh/id_rsa'

2019-07-29 19:05:19,276  - ERROR :  172.16.111.131 BasicPlugin Error:Traceback (most recent call last):
  File "/Users/yky/PycharmProjects/cmdb_db/AutoClient/src/plugins/basic.py", line 49, in linux
    'os_version': self.os_version(),
  File "/Users/yky/PycharmProjects/cmdb_db/AutoClient/src/plugins/basic.py", line 29, in os_version
    output = self.exec_shell_cmd('cat /etc/issue')
  File "/Users/yky/PycharmProjects/cmdb_db/AutoClient/src/plugins/base.py", line 45, in exec_shell_cmd
    output = func(cmd)
  File "/Users/yky/PycharmProjects/cmdb_db/AutoClient/src/plugins/base.py", line 26, in ssh
    private_key = paramiko.RSAKey.from_private_key_file(settings.SSH_PRIVATE_KEY)
  File "/Library/Frameworks/Python.framework/Versions/3.6/lib/python3.6/site-packages/paramiko/pkey.py", line 206, in from_private_key_file
    key = cls(filename=filename, password=password)
  File "/Library/Frameworks/Python.framework/Versions/3.6/lib/python3.6/site-packages/paramiko/rsakey.py", line 55, in __init__
    self._from_private_key_file(filename, password)
  File "/Library/Frameworks/Python.framework/Versions/3.6/lib/python3.6/site-packages/paramiko/rsakey.py", line 175, in _from_private_key_file
    data = self._read_private_key_file("RSA", filename, password)
  File "/Library/Frameworks/Python.framework/Versions/3.6/lib/python3.6/site-packages/paramiko/pkey.py", line 278, in _read_private_key_file
    with open(filename, "r") as f:
FileNotFoundError: [Errno 2] No such file or directory: '/root/.ssh/id_rsa'

2019-07-29 19:07:04,342  - ERROR :  172.16.111.131 BasicPlugin Error:Traceback (most recent call last):
  File "/Users/yky/PycharmProjects/cmdb_db/AutoClient/src/plugins/basic.py", line 49, in linux
    'os_version': self.os_version(),
  File "/Users/yky/PycharmProjects/cmdb_db/AutoClient/src/plugins/basic.py", line 29, in os_version
    output = self.exec_shell_cmd('cat /etc/issue')
  File "/Users/yky/PycharmProjects/cmdb_db/AutoClient/src/plugins/base.py", line 45, in exec_shell_cmd
    output = func(cmd)
  File "/Users/yky/PycharmProjects/cmdb_db/AutoClient/src/plugins/base.py", line 26, in ssh
    private_key = paramiko.RSAKey.from_private_key_file(settings.SSH_PRIVATE_KEY)
  File "/Library/Frameworks/Python.framework/Versions/3.6/lib/python3.6/site-packages/paramiko/pkey.py", line 206, in from_private_key_file
    key = cls(filename=filename, password=password)
  File "/Library/Frameworks/Python.framework/Versions/3.6/lib/python3.6/site-packages/paramiko/rsakey.py", line 55, in __init__
    self._from_private_key_file(filename, password)
  File "/Library/Frameworks/Python.framework/Versions/3.6/lib/python3.6/site-packages/paramiko/rsakey.py", line 175, in _from_private_key_file
    data = self._read_private_key_file("RSA", filename, password)
  File "/Library/Frameworks/Python.framework/Versions/3.6/lib/python3.6/site-packages/paramiko/pkey.py", line 278, in _read_private_key_file
    with open(filename, "r") as f:
FileNotFoundError: [Errno 2] No such file or directory: '/root/.ssh/id_rsa'

2019-07-29 19:15:59,487  - ERROR :  172.16.111.131 BasicPlugin Error:Traceback (most recent call last):
  File "/Users/yky/PycharmProjects/cmdb_db/AutoClient/src/plugins/basic.py", line 49, in linux
    'os_version': self.os_version(),
  File "/Users/yky/PycharmProjects/cmdb_db/AutoClient/src/plugins/basic.py", line 29, in os_version
    output = self.exec_shell_cmd('cat /etc/issue')
  File "/Users/yky/PycharmProjects/cmdb_db/AutoClient/src/plugins/base.py", line 45, in exec_shell_cmd
    output = func(cmd)
  File "/Users/yky/PycharmProjects/cmdb_db/AutoClient/src/plugins/base.py", line 26, in ssh
    private_key = paramiko.RSAKey.from_private_key_file(settings.SSH_PRIVATE_KEY)
  File "/Library/Frameworks/Python.framework/Versions/3.6/lib/python3.6/site-packages/paramiko/pkey.py", line 206, in from_private_key_file
    key = cls(filename=filename, password=password)
  File "/Library/Frameworks/Python.framework/Versions/3.6/lib/python3.6/site-packages/paramiko/rsakey.py", line 55, in __init__
    self._from_private_key_file(filename, password)
  File "/Library/Frameworks/Python.framework/Versions/3.6/lib/python3.6/site-packages/paramiko/rsakey.py", line 175, in _from_private_key_file
    data = self._read_private_key_file("RSA", filename, password)
  File "/Library/Frameworks/Python.framework/Versions/3.6/lib/python3.6/site-packages/paramiko/pkey.py", line 278, in _read_private_key_file
    with open(filename, "r") as f:
FileNotFoundError: [Errno 2] No such file or directory: '/root/.ssh/id_rsa'

2019-07-29 19:16:25,953  - ERROR :  172.16.111.131 BasicPlugin Error:Traceback (most recent call last):
  File "/Users/yky/PycharmProjects/cmdb_db/AutoClient/src/plugins/basic.py", line 49, in linux
    'os_version': self.os_version(),
  File "/Users/yky/PycharmProjects/cmdb_db/AutoClient/src/plugins/basic.py", line 29, in os_version
    output = self.exec_shell_cmd('cat /etc/issue')
  File "/Users/yky/PycharmProjects/cmdb_db/AutoClient/src/plugins/base.py", line 45, in exec_shell_cmd
    output = func(cmd)
  File "/Users/yky/PycharmProjects/cmdb_db/AutoClient/src/plugins/base.py", line 26, in ssh
    private_key = paramiko.RSAKey.from_private_key_file(settings.SSH_PRIVATE_KEY)
  File "/Library/Frameworks/Python.framework/Versions/3.6/lib/python3.6/site-packages/paramiko/pkey.py", line 206, in from_private_key_file
    key = cls(filename=filename, password=password)
  File "/Library/Frameworks/Python.framework/Versions/3.6/lib/python3.6/site-packages/paramiko/rsakey.py", line 55, in __init__
    self._from_private_key_file(filename, password)
  File "/Library/Frameworks/Python.framework/Versions/3.6/lib/python3.6/site-packages/paramiko/rsakey.py", line 175, in _from_private_key_file
    data = self._read_private_key_file("RSA", filename, password)
  File "/Library/Frameworks/Python.framework/Versions/3.6/lib/python3.6/site-packages/paramiko/pkey.py", line 278, in _read_private_key_file
    with open(filename, "r") as f:
FileNotFoundError: [Errno 2] No such file or directory: '/root/.ssh/id_rsa'

2019-07-29 19:16:34,278  - ERROR :  172.16.111.131 BasicPlugin Error:Traceback (most recent call last):
  File "/Users/yky/PycharmProjects/cmdb_db/AutoClient/src/plugins/basic.py", line 49, in linux
    'os_version': self.os_version(),
  File "/Users/yky/PycharmProjects/cmdb_db/AutoClient/src/plugins/basic.py", line 29, in os_version
    output = self.exec_shell_cmd('cat /etc/issue')
  File "/Users/yky/PycharmProjects/cmdb_db/AutoClient/src/plugins/base.py", line 45, in exec_shell_cmd
    output = func(cmd)
  File "/Users/yky/PycharmProjects/cmdb_db/AutoClient/src/plugins/base.py", line 26, in ssh
    private_key = paramiko.RSAKey.from_private_key_file(settings.SSH_PRIVATE_KEY)
  File "/Library/Frameworks/Python.framework/Versions/3.6/lib/python3.6/site-packages/paramiko/pkey.py", line 206, in from_private_key_file
    key = cls(filename=filename, password=password)
  File "/Library/Frameworks/Python.framework/Versions/3.6/lib/python3.6/site-packages/paramiko/rsakey.py", line 55, in __init__
    self._from_private_key_file(filename, password)
  File "/Library/Frameworks/Python.framework/Versions/3.6/lib/python3.6/site-packages/paramiko/rsakey.py", line 175, in _from_private_key_file
    data = self._read_private_key_file("RSA", filename, password)
  File "/Library/Frameworks/Python.framework/Versions/3.6/lib/python3.6/site-packages/paramiko/pkey.py", line 278, in _read_private_key_file
    with open(filename, "r") as f:
FileNotFoundError: [Errno 2] No such file or directory: '/root/.ssh/id_rsa'

2019-07-29 19:25:14,231  - ERROR :  172.16.111.131 BasicPlugin Error:Traceback (most recent call last):
  File "/Users/yky/PycharmProjects/cmdb_db/AutoClient/src/plugins/basic.py", line 49, in linux
    'os_version': self.os_version(),
  File "/Users/yky/PycharmProjects/cmdb_db/AutoClient/src/plugins/basic.py", line 29, in os_version
    output = self.exec_shell_cmd('cat /etc/issue')
  File "/Users/yky/PycharmProjects/cmdb_db/AutoClient/src/plugins/base.py", line 45, in exec_shell_cmd
    output = func(cmd)
  File "/Users/yky/PycharmProjects/cmdb_db/AutoClient/src/plugins/base.py", line 26, in ssh
    private_key = paramiko.RSAKey.from_private_key_file(settings.SSH_PRIVATE_KEY)
  File "/Library/Frameworks/Python.framework/Versions/3.6/lib/python3.6/site-packages/paramiko/pkey.py", line 206, in from_private_key_file
    key = cls(filename=filename, password=password)
  File "/Library/Frameworks/Python.framework/Versions/3.6/lib/python3.6/site-packages/paramiko/rsakey.py", line 55, in __init__
    self._from_private_key_file(filename, password)
  File "/Library/Frameworks/Python.framework/Versions/3.6/lib/python3.6/site-packages/paramiko/rsakey.py", line 175, in _from_private_key_file
    data = self._read_private_key_file("RSA", filename, password)
  File "/Library/Frameworks/Python.framework/Versions/3.6/lib/python3.6/site-packages/paramiko/pkey.py", line 278, in _read_private_key_file
    with open(filename, "r") as f:
FileNotFoundError: [Errno 2] No such file or directory: '/root/.ssh/id_rsa'

2019-07-29 19:27:41,787  - ERROR :  172.16.111.131 BasicPlugin Error:Traceback (most recent call last):
  File "/Users/yky/PycharmProjects/cmdb_db/AutoClient/src/plugins/basic.py", line 49, in linux
    'os_version': self.os_version(),
  File "/Users/yky/PycharmProjects/cmdb_db/AutoClient/src/plugins/basic.py", line 29, in os_version
    output = self.exec_shell_cmd('cat /etc/issue')
  File "/Users/yky/PycharmProjects/cmdb_db/AutoClient/src/plugins/base.py", line 45, in exec_shell_cmd
    output = func(cmd)
  File "/Users/yky/PycharmProjects/cmdb_db/AutoClient/src/plugins/base.py", line 26, in ssh
    private_key = paramiko.RSAKey.from_private_key_file(settings.SSH_PRIVATE_KEY)
  File "/Library/Frameworks/Python.framework/Versions/3.6/lib/python3.6/site-packages/paramiko/pkey.py", line 206, in from_private_key_file
    key = cls(filename=filename, password=password)
  File "/Library/Frameworks/Python.framework/Versions/3.6/lib/python3.6/site-packages/paramiko/rsakey.py", line 55, in __init__
    self._from_private_key_file(filename, password)
  File "/Library/Frameworks/Python.framework/Versions/3.6/lib/python3.6/site-packages/paramiko/rsakey.py", line 175, in _from_private_key_file
    data = self._read_private_key_file("RSA", filename, password)
  File "/Library/Frameworks/Python.framework/Versions/3.6/lib/python3.6/site-packages/paramiko/pkey.py", line 278, in _read_private_key_file
    with open(filename, "r") as f:
FileNotFoundError: [Errno 2] No such file or directory: '/root/.ssh/id_rsa'

2019-07-29 19:30:03,027  - ERROR :  None BasicPlugin Error:Traceback (most recent call last):
  File "/Users/yky/PycharmProjects/cmdb_db/AutoClient/src/plugins/basic.py", line 49, in linux
    'os_version': self.os_version(),
  File "/Users/yky/PycharmProjects/cmdb_db/AutoClient/src/plugins/basic.py", line 29, in os_version
    output = self.exec_shell_cmd('cat /etc/issue')
  File "/Users/yky/PycharmProjects/cmdb_db/AutoClient/src/plugins/base.py", line 45, in exec_shell_cmd
    output = func(cmd)
  File "/Users/yky/PycharmProjects/cmdb_db/AutoClient/src/plugins/base.py", line 26, in ssh
    private_key = paramiko.RSAKey.from_private_key_file(settings.SSH_PRIVATE_KEY)
  File "/Library/Frameworks/Python.framework/Versions/3.6/lib/python3.6/site-packages/paramiko/pkey.py", line 206, in from_private_key_file
    key = cls(filename=filename, password=password)
  File "/Library/Frameworks/Python.framework/Versions/3.6/lib/python3.6/site-packages/paramiko/rsakey.py", line 55, in __init__
    self._from_private_key_file(filename, password)
  File "/Library/Frameworks/Python.framework/Versions/3.6/lib/python3.6/site-packages/paramiko/rsakey.py", line 175, in _from_private_key_file
    data = self._read_private_key_file("RSA", filename, password)
  File "/Library/Frameworks/Python.framework/Versions/3.6/lib/python3.6/site-packages/paramiko/pkey.py", line 278, in _read_private_key_file
    with open(filename, "r") as f:
FileNotFoundError: [Errno 2] No such file or directory: '/root/.ssh/id_rsa'

2019-07-29 19:31:08,681  - ERROR :  [172.16.111.131]资产不存在
2019-07-29 19:32:27,723  - ERROR :  [172.16.111.131]资产不存在
2019-07-29 19:33:27,376  - ERROR :  [172.16.111.131]资产不存在
2019-07-29 20:03:26,618  - ERROR :  172.16.111.131 BasicPlugin Error:Traceback (most recent call last):
  File "/Users/yky/PycharmProjects/cmdb_db/AutoClient/src/plugins/basic.py", line 57, in linux
    'hostname': self.os_hostname(),
  File "/Users/yky/PycharmProjects/cmdb_db/AutoClient/src/plugins/basic.py", line 46, in os_hostname
    'select ip,hostname from cmdb.MysqlInfo where hostname = "{}"'.format(hostname))
TypeError: getinfo() missing 1 required positional argument: 'sql'

2019-07-29 20:04:01,795  - ERROR :  172.16.111.131 BasicPlugin Error:Traceback (most recent call last):
  File "/Users/yky/PycharmProjects/cmdb_db/AutoClient/src/plugins/basic.py", line 58, in linux
    'hostname': self.os_hostname(),
  File "/Users/yky/PycharmProjects/cmdb_db/AutoClient/src/plugins/basic.py", line 46, in os_hostname
    'select ip,hostname from cmdb.MysqlInfo where hostname = "{}"'.format(hostname))
TypeError: getinfo() missing 1 required positional argument: 'sql'

2019-07-29 20:05:39,450  - ERROR :  172.16.111.131 BasicPlugin Error:Traceback (most recent call last):
  File "/Users/yky/PycharmProjects/cmdb_db/AutoClient/src/plugins/basic.py", line 58, in linux
    'hostname': self.os_hostname(),
  File "/Users/yky/PycharmProjects/cmdb_db/AutoClient/src/plugins/basic.py", line 46, in os_hostname
    'select ip,hostname from cmdb.MysqlInfo where hostname = "{}"'.format(hostname))
TypeError: getinfo() missing 1 required positional argument: 'sql'

2019-07-29 20:07:14,554  - ERROR :  mysql1 BasicPlugin Error:Traceback (most recent call last):
  File "/Users/yky/PycharmProjects/cmdb_db/AutoClient/src/plugins/basic.py", line 58, in linux
    'hostname': self.os_hostname(),
  File "/Users/yky/PycharmProjects/cmdb_db/AutoClient/src/plugins/basic.py", line 46, in os_hostname
    'select ip,hostname from cmdb.MysqlInfo where hostname = "{}"'.format(hostname))
TypeError: getinfo() missing 1 required positional argument: 'sql'

2019-07-29 20:07:30,190  - ERROR :  mysql1 BasicPlugin Error:Traceback (most recent call last):
  File "/Users/yky/PycharmProjects/cmdb_db/AutoClient/src/plugins/basic.py", line 58, in linux
    'hostname': self.os_hostname(),
  File "/Users/yky/PycharmProjects/cmdb_db/AutoClient/src/plugins/basic.py", line 46, in os_hostname
    'select ip,hostname from cmdb.MysqlInfo where hostname = "{}"'.format(hostname))
TypeError: getinfo() missing 1 required positional argument: 'sql'

2019-07-29 20:13:00,857  - ERROR :  mysql1 BasicPlugin Error:Traceback (most recent call last):
  File "/Users/yky/PycharmProjects/cmdb_db/AutoClient/src/plugins/basic.py", line 58, in linux
    'hostname': self.os_hostname(),
  File "/Users/yky/PycharmProjects/cmdb_db/AutoClient/src/plugins/basic.py", line 46, in os_hostname
    'select ip,hostname from cmdb.MysqlInfo where hostname = "{}"'.format(self.hostname),)
TypeError: getinfo() missing 1 required positional argument: 'sql'

2019-07-29 20:17:34,495  - ERROR :  mysql1 BasicPlugin Error:Traceback (most recent call last):
  File "/Users/yky/PycharmProjects/cmdb_db/AutoClient/src/plugins/basic.py", line 57, in linux
    'hostname': self.os_hostname(),
  File "/Users/yky/PycharmProjects/cmdb_db/AutoClient/src/plugins/basic.py", line 46, in os_hostname
    'select ip,hostname from cmdb_mha.MysqlInfo where hostname = "{}"'.format(self.hostname),)
TypeError: getinfo() missing 1 required positional argument: 'sql'

2019-07-29 20:17:44,450  - ERROR :  mysql1 BasicPlugin Error:Traceback (most recent call last):
  File "/Users/yky/PycharmProjects/cmdb_db/AutoClient/src/plugins/basic.py", line 57, in linux
    'hostname': self.os_hostname(),
  File "/Users/yky/PycharmProjects/cmdb_db/AutoClient/src/plugins/basic.py", line 46, in os_hostname
    'select ip,hostname from cmdb_mha.MysqlInfo where hostname = "{}"'.format(self.hostname),)
TypeError: getinfo() missing 1 required positional argument: 'sql'

2019-07-29 20:18:11,435  - ERROR :  mysql1 BasicPlugin Error:Traceback (most recent call last):
  File "/Users/yky/PycharmProjects/cmdb_db/AutoClient/src/plugins/basic.py", line 57, in linux
    'hostname': self.os_hostname(),
  File "/Users/yky/PycharmProjects/cmdb_db/AutoClient/src/plugins/basic.py", line 46, in os_hostname
    'select ip,hostname from cmdb_mha.MysqlInfo where hostname = "{}"'.format(hostname),)
TypeError: getinfo() missing 1 required positional argument: 'sql'

2019-07-29 20:21:47,156  - ERROR :  mysql1 BasicPlugin Error:Traceback (most recent call last):
  File "/Users/yky/PycharmProjects/cmdb_db/AutoClient/src/plugins/basic.py", line 57, in linux
    'hostname': self.os_hostname(),
  File "/Users/yky/PycharmProjects/cmdb_db/AutoClient/src/plugins/basic.py", line 46, in os_hostname
    'select ip,hostname from cmdb_mha.MysqlInfo where hostname = "{}"'.format(hostname),)
TypeError: getinfo() missing 1 required positional argument: 'sql'

2019-07-29 20:22:18,897  - ERROR :  mysql1 BasicPlugin Error:Traceback (most recent call last):
  File "/Users/yky/PycharmProjects/cmdb_db/AutoClient/src/plugins/basic.py", line 57, in linux
    'hostname': self.os_hostname(),
  File "/Users/yky/PycharmProjects/cmdb_db/AutoClient/src/plugins/basic.py", line 46, in os_hostname
    'select ip,hostname from cmdb_mha.MysqlInfo where hostname = "{}"'.format(hostname),)
TypeError: getinfo() missing 1 required positional argument: 'sql'

2019-07-29 20:25:02,738  - ERROR :  mysql1 BasicPlugin Error:Traceback (most recent call last):
  File "/Users/yky/PycharmProjects/cmdb_db/AutoClient/src/plugins/basic.py", line 57, in linux
    'hostname': self.os_hostname(),
  File "/Users/yky/PycharmProjects/cmdb_db/AutoClient/src/plugins/basic.py", line 46, in os_hostname
    'select ip,hostname from cmdb_mha.MysqlInfo where hostname = "%s"', [self.hostname])
  File "/Users/yky/PycharmProjects/cmdb_db/AutoClient/src/plugins/database.py", line 28, in getinfo
    conn = pymysql.connect(host=self.host, user=self.user, port=self.port, password=self.passwd,
AttributeError: 'str' object has no attribute 'host'

2019-07-29 20:27:37,528  - ERROR :  mysql1 BasicPlugin Error:Traceback (most recent call last):
  File "/Users/yky/PycharmProjects/cmdb_db/AutoClient/src/plugins/basic.py", line 62, in linux
    'hostname': self.os_hostname(),
  File "/Users/yky/PycharmProjects/cmdb_db/AutoClient/src/plugins/basic.py", line 52, in os_hostname
    output = tmp_result['ip']
TypeError: 'NoneType' object is not subscriptable

2019-07-29 20:35:56,838  - ERROR :  mysql1 BasicPlugin Error:Traceback (most recent call last):
  File "/Users/yky/PycharmProjects/cmdb_db/AutoClient/src/plugins/basic.py", line 62, in linux
    'hostname': self.os_hostname(),
  File "/Users/yky/PycharmProjects/cmdb_db/AutoClient/src/plugins/basic.py", line 52, in os_hostname
    output = tmp_result['ip']
TypeError: list indices must be integers or slices, not str

2019-07-29 20:36:36,769  - ERROR :  mysql1 Mysql info collect fail Traceback (most recent call last):
  File "/Users/yky/PycharmProjects/cmdb_db/AutoClient/src/plugins/database.py", line 61, in linux
    port=item['port'],
KeyError: 'port'

2019-07-29 20:36:36,785  - ERROR :  [172.16.111.131]资产不存在
2019-07-29 20:37:01,068  - ERROR :  mysql1 Mysql info collect fail Traceback (most recent call last):
  File "/Users/yky/PycharmProjects/cmdb_db/AutoClient/src/plugins/database.py", line 61, in linux
    port=item['port'],
KeyError: 'port'

2019-07-29 20:37:01,079  - ERROR :  [172.16.111.131]资产不存在
2019-07-29 20:37:28,540  - ERROR :  mysql1 BasicPlugin Error:Traceback (most recent call last):
  File "/Users/yky/PycharmProjects/cmdb_db/AutoClient/src/plugins/basic.py", line 61, in linux
    'hostname': self.os_hostname(),
  File "/Users/yky/PycharmProjects/cmdb_db/AutoClient/src/plugins/basic.py", line 43, in os_hostname
    hostname = self.exec_shell_cmd('hostname')
  File "/Users/yky/PycharmProjects/cmdb_db/AutoClient/src/plugins/base.py", line 45, in exec_shell_cmd
    output = func(cmd)
  File "/Users/yky/PycharmProjects/cmdb_db/AutoClient/src/plugins/base.py", line 26, in ssh
    private_key = paramiko.RSAKey.from_private_key_file(settings.SSH_PRIVATE_KEY)
  File "/Library/Frameworks/Python.framework/Versions/3.6/lib/python3.6/site-packages/paramiko/pkey.py", line 206, in from_private_key_file
    key = cls(filename=filename, password=password)
  File "/Library/Frameworks/Python.framework/Versions/3.6/lib/python3.6/site-packages/paramiko/rsakey.py", line 55, in __init__
    self._from_private_key_file(filename, password)
  File "/Library/Frameworks/Python.framework/Versions/3.6/lib/python3.6/site-packages/paramiko/rsakey.py", line 175, in _from_private_key_file
    data = self._read_private_key_file("RSA", filename, password)
  File "/Library/Frameworks/Python.framework/Versions/3.6/lib/python3.6/site-packages/paramiko/pkey.py", line 278, in _read_private_key_file
    with open(filename, "r") as f:
FileNotFoundError: [Errno 2] No such file or directory: '/root/.ssh/id_rsa'

2019-07-29 20:37:44,333  - ERROR :  mysql1 Mysql info collect fail Traceback (most recent call last):
  File "/Users/yky/PycharmProjects/cmdb_db/AutoClient/src/plugins/database.py", line 61, in linux
    port=item['port'],
KeyError: 'port'

2019-07-29 20:37:44,343  - ERROR :  [172.16.111.131]资产不存在
2019-07-29 20:53:04,239  - ERROR :  mysql1 Mysql info collect fail Traceback (most recent call last):
  File "/Users/yky/PycharmProjects/cmdb_db/AutoClient/src/plugins/database.py", line 61, in linux
    port=item['port'],
KeyError: 'port'

2019-07-29 20:53:04,252  - ERROR :  [172.16.111.131]资产不存在
2019-07-29 20:55:57,641  - ERROR :  mysql1 BasicPlugin Error:Traceback (most recent call last):
  File "/Users/yky/PycharmProjects/cmdb_db/AutoClient/src/plugins/basic.py", line 63, in linux
    'hostname': self.os_hostname(),
  File "/Users/yky/PycharmProjects/cmdb_db/AutoClient/src/plugins/basic.py", line 43, in os_hostname
    hostname = self.exec_shell_cmd('hostname')
  File "/Users/yky/PycharmProjects/cmdb_db/AutoClient/src/plugins/base.py", line 45, in exec_shell_cmd
    output = func(cmd)
  File "/Users/yky/PycharmProjects/cmdb_db/AutoClient/src/plugins/base.py", line 26, in ssh
    private_key = paramiko.RSAKey.from_private_key_file(settings.SSH_PRIVATE_KEY)
  File "/Library/Frameworks/Python.framework/Versions/3.6/lib/python3.6/site-packages/paramiko/pkey.py", line 206, in from_private_key_file
    key = cls(filename=filename, password=password)
  File "/Library/Frameworks/Python.framework/Versions/3.6/lib/python3.6/site-packages/paramiko/rsakey.py", line 55, in __init__
    self._from_private_key_file(filename, password)
  File "/Library/Frameworks/Python.framework/Versions/3.6/lib/python3.6/site-packages/paramiko/rsakey.py", line 175, in _from_private_key_file
    data = self._read_private_key_file("RSA", filename, password)
  File "/Library/Frameworks/Python.framework/Versions/3.6/lib/python3.6/site-packages/paramiko/pkey.py", line 278, in _read_private_key_file
    with open(filename, "r") as f:
FileNotFoundError: [Errno 2] No such file or directory: '/root/.ssh/id_rsa'

2019-07-29 20:56:46,178  - ERROR :  mysql1 BasicPlugin Error:Traceback (most recent call last):
  File "/Users/yky/PycharmProjects/cmdb_db/AutoClient/src/plugins/basic.py", line 63, in linux
    'hostname': self.os_hostname(),
  File "/Users/yky/PycharmProjects/cmdb_db/AutoClient/src/plugins/basic.py", line 43, in os_hostname
    hostname = self.exec_shell_cmd('hostname')
  File "/Users/yky/PycharmProjects/cmdb_db/AutoClient/src/plugins/base.py", line 46, in exec_shell_cmd
    output = func(cmd)
  File "/Users/yky/PycharmProjects/cmdb_db/AutoClient/src/plugins/base.py", line 26, in ssh
    private_key = paramiko.RSAKey.from_private_key_file(settings.SSH_PRIVATE_KEY)
  File "/Library/Frameworks/Python.framework/Versions/3.6/lib/python3.6/site-packages/paramiko/pkey.py", line 206, in from_private_key_file
    key = cls(filename=filename, password=password)
  File "/Library/Frameworks/Python.framework/Versions/3.6/lib/python3.6/site-packages/paramiko/rsakey.py", line 55, in __init__
    self._from_private_key_file(filename, password)
  File "/Library/Frameworks/Python.framework/Versions/3.6/lib/python3.6/site-packages/paramiko/rsakey.py", line 175, in _from_private_key_file
    data = self._read_private_key_file("RSA", filename, password)
  File "/Library/Frameworks/Python.framework/Versions/3.6/lib/python3.6/site-packages/paramiko/pkey.py", line 278, in _read_private_key_file
    with open(filename, "r") as f:
FileNotFoundError: [Errno 2] No such file or directory: '/root/.ssh/id_rsa'

2019-07-29 21:07:46,596  - ERROR :  5e6348bc3336 Mysql info collect fail Traceback (most recent call last):
  File "/Users/yky/PycharmProjects/cmdb_db/AutoClient/src/plugins/database.py", line 61, in linux
    port=item['port'],
KeyError: 'port'

2019-07-29 21:07:46,609  - ERROR :  [172.16.111.131]资产不存在
2019-07-29 22:15:25,881  - ERROR :  5e6348bc3336 BasicPlugin Error:Traceback (most recent call last):
  File "/Users/yky/PycharmProjects/cmdb_db/AutoClient/src/plugins/basic.py", line 63, in linux
    'hostname': self.os_hostname(),
  File "/Users/yky/PycharmProjects/cmdb_db/AutoClient/src/plugins/basic.py", line 43, in os_hostname
    hostname = self.exec_shell_cmd('hostname')
  File "/Users/yky/PycharmProjects/cmdb_db/AutoClient/src/plugins/base.py", line 45, in exec_shell_cmd
    output = func(cmd)
  File "/Users/yky/PycharmProjects/cmdb_db/AutoClient/src/plugins/base.py", line 26, in ssh
    private_key = paramiko.RSAKey.from_private_key_file(settings.SSH_PRIVATE_KEY)
  File "/Library/Frameworks/Python.framework/Versions/3.6/lib/python3.6/site-packages/paramiko/pkey.py", line 206, in from_private_key_file
    key = cls(filename=filename, password=password)
  File "/Library/Frameworks/Python.framework/Versions/3.6/lib/python3.6/site-packages/paramiko/rsakey.py", line 55, in __init__
    self._from_private_key_file(filename, password)
  File "/Library/Frameworks/Python.framework/Versions/3.6/lib/python3.6/site-packages/paramiko/rsakey.py", line 175, in _from_private_key_file
    data = self._read_private_key_file("RSA", filename, password)
  File "/Library/Frameworks/Python.framework/Versions/3.6/lib/python3.6/site-packages/paramiko/pkey.py", line 278, in _read_private_key_file
    with open(filename, "r") as f:
FileNotFoundError: [Errno 2] No such file or directory: '/root/.ssh/id_rsa'

2019-07-29 22:15:25,881  - ERROR :  ykydeMacBook-Pro.local BasicPlugin Error:Traceback (most recent call last):
  File "/Users/yky/PycharmProjects/cmdb_db/AutoClient/src/plugins/basic.py", line 63, in linux
    'hostname': self.os_hostname(),
  File "/Users/yky/PycharmProjects/cmdb_db/AutoClient/src/plugins/basic.py", line 43, in os_hostname
    hostname = self.exec_shell_cmd('hostname')
  File "/Users/yky/PycharmProjects/cmdb_db/AutoClient/src/plugins/base.py", line 45, in exec_shell_cmd
    output = func(cmd)
  File "/Users/yky/PycharmProjects/cmdb_db/AutoClient/src/plugins/base.py", line 26, in ssh
    private_key = paramiko.RSAKey.from_private_key_file(settings.SSH_PRIVATE_KEY)
  File "/Library/Frameworks/Python.framework/Versions/3.6/lib/python3.6/site-packages/paramiko/pkey.py", line 206, in from_private_key_file
    key = cls(filename=filename, password=password)
  File "/Library/Frameworks/Python.framework/Versions/3.6/lib/python3.6/site-packages/paramiko/rsakey.py", line 55, in __init__
    self._from_private_key_file(filename, password)
  File "/Library/Frameworks/Python.framework/Versions/3.6/lib/python3.6/site-packages/paramiko/rsakey.py", line 175, in _from_private_key_file
    data = self._read_private_key_file("RSA", filename, password)
  File "/Library/Frameworks/Python.framework/Versions/3.6/lib/python3.6/site-packages/paramiko/pkey.py", line 278, in _read_private_key_file
    with open(filename, "r") as f:
FileNotFoundError: [Errno 2] No such file or directory: '/root/.ssh/id_rsa'

2019-07-29 22:16:27,687  - ERROR :  5e6348bc3336 BasicPlugin Error:Traceback (most recent call last):
  File "/Users/yky/PycharmProjects/cmdb_db/AutoClient/src/plugins/basic.py", line 63, in linux
    'hostname': self.os_hostname(),
  File "/Users/yky/PycharmProjects/cmdb_db/AutoClient/src/plugins/basic.py", line 43, in os_hostname
    hostname = self.exec_shell_cmd('hostname')
  File "/Users/yky/PycharmProjects/cmdb_db/AutoClient/src/plugins/base.py", line 45, in exec_shell_cmd
    output = func(cmd)
  File "/Users/yky/PycharmProjects/cmdb_db/AutoClient/src/plugins/base.py", line 29, in ssh
    ssh.connect(hostname=self.hostname, port=settings.SSH_PORT, username=settings.SSH_USER, pkey=private_key)
  File "/Library/Frameworks/Python.framework/Versions/3.6/lib/python3.6/site-packages/paramiko/client.py", line 334, in connect
    to_try = list(self._families_and_addresses(hostname, port))
  File "/Library/Frameworks/Python.framework/Versions/3.6/lib/python3.6/site-packages/paramiko/client.py", line 204, in _families_and_addresses
    hostname, port, socket.AF_UNSPEC, socket.SOCK_STREAM
  File "/Library/Frameworks/Python.framework/Versions/3.6/lib/python3.6/socket.py", line 745, in getaddrinfo
    for res in _socket.getaddrinfo(host, port, family, type, proto, flags):
socket.gaierror: [Errno 8] nodename nor servname provided, or not known

2019-07-29 22:16:27,808  - ERROR :  ykydeMacBook-Pro.local BasicPlugin Error:Traceback (most recent call last):
  File "/Users/yky/PycharmProjects/cmdb_db/AutoClient/src/plugins/basic.py", line 63, in linux
    'hostname': self.os_hostname(),
  File "/Users/yky/PycharmProjects/cmdb_db/AutoClient/src/plugins/basic.py", line 43, in os_hostname
    hostname = self.exec_shell_cmd('hostname')
  File "/Users/yky/PycharmProjects/cmdb_db/AutoClient/src/plugins/base.py", line 45, in exec_shell_cmd
    output = func(cmd)
  File "/Users/yky/PycharmProjects/cmdb_db/AutoClient/src/plugins/base.py", line 29, in ssh
    ssh.connect(hostname=self.hostname, port=settings.SSH_PORT, username=settings.SSH_USER, pkey=private_key)
  File "/Library/Frameworks/Python.framework/Versions/3.6/lib/python3.6/site-packages/paramiko/client.py", line 362, in connect
    raise NoValidConnectionsError(errors)
paramiko.ssh_exception.NoValidConnectionsError: [Errno None] Unable to connect to port 22 on 172.16.111.1, 192.168.0.104, 192.168.49.1 or fe80::1092:ebb6:6f19:e4dc%en0

2019-07-29 22:20:25,138  - ERROR :  5e6348bc3336 BasicPlugin Error:Traceback (most recent call last):
  File "/Users/yky/PycharmProjects/cmdb_db/AutoClient/src/plugins/basic.py", line 63, in linux
    'hostname': self.os_hostname(),
  File "/Users/yky/PycharmProjects/cmdb_db/AutoClient/src/plugins/basic.py", line 43, in os_hostname
    hostname = self.exec_shell_cmd('hostname')
  File "/Users/yky/PycharmProjects/cmdb_db/AutoClient/src/plugins/base.py", line 45, in exec_shell_cmd
    output = func(cmd)
  File "/Users/yky/PycharmProjects/cmdb_db/AutoClient/src/plugins/base.py", line 29, in ssh
    ssh.connect(hostname=self.hostname, port=settings.SSH_PORT, username=settings.SSH_USER, pkey=private_key)
  File "/Library/Frameworks/Python.framework/Versions/3.6/lib/python3.6/site-packages/paramiko/client.py", line 334, in connect
    to_try = list(self._families_and_addresses(hostname, port))
  File "/Library/Frameworks/Python.framework/Versions/3.6/lib/python3.6/site-packages/paramiko/client.py", line 204, in _families_and_addresses
    hostname, port, socket.AF_UNSPEC, socket.SOCK_STREAM
  File "/Library/Frameworks/Python.framework/Versions/3.6/lib/python3.6/socket.py", line 745, in getaddrinfo
    for res in _socket.getaddrinfo(host, port, family, type, proto, flags):
socket.gaierror: [Errno 8] nodename nor servname provided, or not known

2019-07-29 22:20:25,300  - ERROR :  ykydeMacBook-Pro.local BasicPlugin Error:Traceback (most recent call last):
  File "/Users/yky/PycharmProjects/cmdb_db/AutoClient/src/plugins/basic.py", line 63, in linux
    'hostname': self.os_hostname(),
  File "/Users/yky/PycharmProjects/cmdb_db/AutoClient/src/plugins/basic.py", line 43, in os_hostname
    hostname = self.exec_shell_cmd('hostname')
  File "/Users/yky/PycharmProjects/cmdb_db/AutoClient/src/plugins/base.py", line 45, in exec_shell_cmd
    output = func(cmd)
  File "/Users/yky/PycharmProjects/cmdb_db/AutoClient/src/plugins/base.py", line 29, in ssh
    ssh.connect(hostname=self.hostname, port=settings.SSH_PORT, username=settings.SSH_USER, pkey=private_key)
  File "/Library/Frameworks/Python.framework/Versions/3.6/lib/python3.6/site-packages/paramiko/client.py", line 362, in connect
    raise NoValidConnectionsError(errors)
paramiko.ssh_exception.NoValidConnectionsError: [Errno None] Unable to connect to port 22 on 172.16.111.1, 192.168.0.104, 192.168.49.1 or fe80::1092:ebb6:6f19:e4dc%en0

2019-07-29 22:23:01,922  - ERROR :  5e6348bc3336 BasicPlugin Error:Traceback (most recent call last):
  File "/Users/yky/PycharmProjects/cmdb_db/AutoClient/src/plugins/basic.py", line 63, in linux
    'hostname': self.os_hostname(),
  File "/Users/yky/PycharmProjects/cmdb_db/AutoClient/src/plugins/basic.py", line 43, in os_hostname
    hostname = self.exec_shell_cmd('hostname')
  File "/Users/yky/PycharmProjects/cmdb_db/AutoClient/src/plugins/base.py", line 45, in exec_shell_cmd
    output = func(cmd)
  File "/Users/yky/PycharmProjects/cmdb_db/AutoClient/src/plugins/base.py", line 29, in ssh
    ssh.connect(hostname=self.hostname, port=settings.SSH_PORT, username=settings.SSH_USER, pkey=private_key)
  File "/Library/Frameworks/Python.framework/Versions/3.6/lib/python3.6/site-packages/paramiko/client.py", line 334, in connect
    to_try = list(self._families_and_addresses(hostname, port))
  File "/Library/Frameworks/Python.framework/Versions/3.6/lib/python3.6/site-packages/paramiko/client.py", line 204, in _families_and_addresses
    hostname, port, socket.AF_UNSPEC, socket.SOCK_STREAM
  File "/Library/Frameworks/Python.framework/Versions/3.6/lib/python3.6/socket.py", line 745, in getaddrinfo
    for res in _socket.getaddrinfo(host, port, family, type, proto, flags):
socket.gaierror: [Errno 8] nodename nor servname provided, or not known

2019-07-29 22:23:02,092  - ERROR :  ykydeMacBook-Pro.local BasicPlugin Error:Traceback (most recent call last):
  File "/Users/yky/PycharmProjects/cmdb_db/AutoClient/src/plugins/basic.py", line 63, in linux
    'hostname': self.os_hostname(),
  File "/Users/yky/PycharmProjects/cmdb_db/AutoClient/src/plugins/basic.py", line 43, in os_hostname
    hostname = self.exec_shell_cmd('hostname')
  File "/Users/yky/PycharmProjects/cmdb_db/AutoClient/src/plugins/base.py", line 45, in exec_shell_cmd
    output = func(cmd)
  File "/Users/yky/PycharmProjects/cmdb_db/AutoClient/src/plugins/base.py", line 29, in ssh
    ssh.connect(hostname=self.hostname, port=settings.SSH_PORT, username=settings.SSH_USER, pkey=private_key)
  File "/Library/Frameworks/Python.framework/Versions/3.6/lib/python3.6/site-packages/paramiko/client.py", line 362, in connect
    raise NoValidConnectionsError(errors)
paramiko.ssh_exception.NoValidConnectionsError: [Errno None] Unable to connect to port 22 on 172.16.111.1, 192.168.0.104, 192.168.49.1 or fe80::1092:ebb6:6f19:e4dc%en0

2019-07-29 22:31:40,031  - ERROR :  ykydeMacBook-Pro.local BasicPlugin Error:Traceback (most recent call last):
  File "/Users/yky/PycharmProjects/cmdb_db/AutoClient/src/plugins/basic.py", line 63, in linux
    'hostname': self.os_hostname(),
  File "/Users/yky/PycharmProjects/cmdb_db/AutoClient/src/plugins/basic.py", line 43, in os_hostname
    hostname = self.exec_shell_cmd('hostname')
  File "/Users/yky/PycharmProjects/cmdb_db/AutoClient/src/plugins/base.py", line 45, in exec_shell_cmd
    output = func(cmd)
  File "/Users/yky/PycharmProjects/cmdb_db/AutoClient/src/plugins/base.py", line 29, in ssh
    ssh.connect(hostname=self.hostname, port=settings.SSH_PORT, username=settings.SSH_USER, pkey=private_key)
  File "/Library/Frameworks/Python.framework/Versions/3.6/lib/python3.6/site-packages/paramiko/client.py", line 362, in connect
    raise NoValidConnectionsError(errors)
paramiko.ssh_exception.NoValidConnectionsError: [Errno None] Unable to connect to port 22 on 192.168.0.104 or fe80::1092:ebb6:6f19:e4dc%en0

2019-07-29 22:31:40,039  - ERROR :  5e6348bc3336 BasicPlugin Error:Traceback (most recent call last):
  File "/Users/yky/PycharmProjects/cmdb_db/AutoClient/src/plugins/basic.py", line 63, in linux
    'hostname': self.os_hostname(),
  File "/Users/yky/PycharmProjects/cmdb_db/AutoClient/src/plugins/basic.py", line 43, in os_hostname
    hostname = self.exec_shell_cmd('hostname')
  File "/Users/yky/PycharmProjects/cmdb_db/AutoClient/src/plugins/base.py", line 45, in exec_shell_cmd
    output = func(cmd)
  File "/Users/yky/PycharmProjects/cmdb_db/AutoClient/src/plugins/base.py", line 29, in ssh
    ssh.connect(hostname=self.hostname, port=settings.SSH_PORT, username=settings.SSH_USER, pkey=private_key)
  File "/Library/Frameworks/Python.framework/Versions/3.6/lib/python3.6/site-packages/paramiko/client.py", line 334, in connect
    to_try = list(self._families_and_addresses(hostname, port))
  File "/Library/Frameworks/Python.framework/Versions/3.6/lib/python3.6/site-packages/paramiko/client.py", line 204, in _families_and_addresses
    hostname, port, socket.AF_UNSPEC, socket.SOCK_STREAM
  File "/Library/Frameworks/Python.framework/Versions/3.6/lib/python3.6/socket.py", line 745, in getaddrinfo
    for res in _socket.getaddrinfo(host, port, family, type, proto, flags):
socket.gaierror: [Errno 8] nodename nor servname provided, or not known

2019-07-29 22:43:31,421  - ERROR :  5e6348bc3336 BasicPlugin Error:Traceback (most recent call last):
  File "/Users/yky/PycharmProjects/cmdb_db/AutoClient/src/plugins/basic.py", line 63, in linux
    'hostname': self.os_hostname(),
  File "/Users/yky/PycharmProjects/cmdb_db/AutoClient/src/plugins/basic.py", line 43, in os_hostname
    hostname = self.exec_shell_cmd('hostname')
  File "/Users/yky/PycharmProjects/cmdb_db/AutoClient/src/plugins/base.py", line 45, in exec_shell_cmd
    output = func(cmd)
  File "/Users/yky/PycharmProjects/cmdb_db/AutoClient/src/plugins/base.py", line 29, in ssh
    ssh.connect(hostname=self.hostname, port=settings.SSH_PORT, username=settings.SSH_USER, pkey=private_key)
  File "/Library/Frameworks/Python.framework/Versions/3.6/lib/python3.6/site-packages/paramiko/client.py", line 334, in connect
    to_try = list(self._families_and_addresses(hostname, port))
  File "/Library/Frameworks/Python.framework/Versions/3.6/lib/python3.6/site-packages/paramiko/client.py", line 204, in _families_and_addresses
    hostname, port, socket.AF_UNSPEC, socket.SOCK_STREAM
  File "/Library/Frameworks/Python.framework/Versions/3.6/lib/python3.6/socket.py", line 745, in getaddrinfo
    for res in _socket.getaddrinfo(host, port, family, type, proto, flags):
socket.gaierror: [Errno 8] nodename nor servname provided, or not known

2019-07-29 22:43:31,565  - ERROR :  ykydeMacBook-Pro.local BasicPlugin Error:Traceback (most recent call last):
  File "/Users/yky/PycharmProjects/cmdb_db/AutoClient/src/plugins/basic.py", line 63, in linux
    'hostname': self.os_hostname(),
  File "/Users/yky/PycharmProjects/cmdb_db/AutoClient/src/plugins/basic.py", line 43, in os_hostname
    hostname = self.exec_shell_cmd('hostname')
  File "/Users/yky/PycharmProjects/cmdb_db/AutoClient/src/plugins/base.py", line 45, in exec_shell_cmd
    output = func(cmd)
  File "/Users/yky/PycharmProjects/cmdb_db/AutoClient/src/plugins/base.py", line 29, in ssh
    ssh.connect(hostname=self.hostname, port=settings.SSH_PORT, username=settings.SSH_USER, pkey=private_key)
  File "/Library/Frameworks/Python.framework/Versions/3.6/lib/python3.6/site-packages/paramiko/client.py", line 362, in connect
    raise NoValidConnectionsError(errors)
paramiko.ssh_exception.NoValidConnectionsError: [Errno None] Unable to connect to port 22 on 172.16.111.1, 192.168.0.104, 192.168.49.1 or fe80::1092:ebb6:6f19:e4dc%en0

2019-07-29 22:58:54,102  - ERROR :  ykydeMacBook-Pro.local Mysql info collect fail Traceback (most recent call last):
  File "/Users/yky/PycharmProjects/cmdb_db/AutoClient/src/plugins/database.py", line 61, in linux
    port=item['port'],
KeyError: 'port'

2019-07-29 22:58:54,103  - ERROR :  5e6348bc3336 Mysql info collect fail Traceback (most recent call last):
  File "/Users/yky/PycharmProjects/cmdb_db/AutoClient/src/plugins/database.py", line 61, in linux
    port=item['port'],
KeyError: 'port'

2019-07-29 22:58:54,119  - ERROR :  [172.16.111.131]资产不存在
2019-07-29 22:58:54,119  - ERROR :  [172.16.111.131]资产不存在
2019-07-29 23:03:36,632  - ERROR :  5e6348bc3336 Mysql info collect fail Traceback (most recent call last):
  File "/Users/yky/PycharmProjects/cmdb_db/AutoClient/src/plugins/database.py", line 61, in linux
    port=item['port'],
KeyError: 'port'

2019-07-29 23:03:36,646  - ERROR :  [172.16.111.131]资产不存在
2019-07-30 09:36:16,669  - ERROR :  [172.16.111.131]资产不存在
2019-07-30 09:36:17,031  - ERROR :  [172.16.111.131]资产不存在
2019-07-30 09:36:22,819  - ERROR :  [172.16.111.131]资产不存在
2019-07-30 09:36:22,822  - ERROR :  [172.16.111.131]资产不存在
